<?xml version="1.0"?>
<robot xmlns:xacro="http://ros.org/wiki/xacro">

	<xacro:include filename="$(find ar600_description)/urdf/head/head.gazebo.xacro" />
  	<!--<xacro:include filename="$(find ar600_description)/urdf/head/head.transmission.xacro" />-->

  	<xacro:macro name="ar600_head_xacro" params="name parent *origin">
  		<link name="${name}_link">
			<visual>
				<geometry>
					<mesh filename="package://ar600_description/meshes/head_low.dae"/>
				</geometry>								
			</visual>
			<inertial>
				<mass value="1"/>
				<inertia 
					 ixx="1.0" ixy="0.0" ixz="0.0" 
					 		   iyy="1.0" iyz="0.0" 
					 		             izz="1.0"/>
			</inertial>			
			<collision>
				<geometry>
					<mesh filename="package://ar600_description/meshes/phys_model/head.stl"/>
				</geometry>					
		
			</collision>		
  		</link>

  		<link name="head_mount">
			<inertial>
				<mass value=".1"/>
				<inertia 
					 ixx="1.0" ixy="0.0" ixz="0.0" 
					           iyy="1.0" iyz="0.0" 
					                     izz="1.0"/>
			</inertial>			
  		</link>

		<link name="head_tilt_mount">
			<inertial>
				<mass value=".1"/>
				<inertia 
					 ixx="1.0" ixy="0.0" ixz="0.0" 
					 		   iyy="1.0" iyz="0.0" 
					 		   			 izz="1.0"/>
			</inertial>			
  		</link>

  		<joint name="torso_head_mount" type="revolute">
			<parent link="${parent}_link"/>
			<child link="head_mount"/>
			<xacro:insert_block name="origin"/>
			<limit effort="1000.0" lower="-0.548" upper="0.548" velocity="0.5"/>
			<axis xyz="0 0 1"/>		
			<dynamics damping="0.7" />
		</joint>

  		<joint name="mount_head_tilt_mount" type="revolute">
			<parent link="head_mount"/>
			<child link="head_tilt_mount"/>
			<origin xyz="0 0 0" rpy="0 0 0"/>
			<limit effort="1000.0" lower="-.1" upper="0.1" velocity="0.5"/>
			<axis xyz="1 0 0"/>		
			<dynamics damping="0.7" />
		</joint>

		<joint name="head_mount_head" type="revolute">
			<parent link="head_tilt_mount"/>
			<child link="${name}_link"/>
			<limit effort="1000.0" lower="-0.25" upper="0.25" velocity="0.5"/>
			<axis xyz="0 1 0"/>
			<dynamics damping="0.7" />
			<origin xyz="0 0 0" rpy="0 0 0"/>
		</joint>

		<!--<xacro:ar600_head_transmission/>-->
  	</xacro:macro>
</robot>