<?xml version="1.0" ?>
<!-- =================================================================================== -->
<!-- |    This document was autogenerated by xacro from ar_low.xml                     | -->
<!-- |    EDITING THIS FILE BY HAND IS NOT RECOMMENDED                                 | -->
<!-- =================================================================================== -->
<robot name="ar600" xmlns:xacro="http://www.ros.org/wiki/xacro">
  <!-- <xacro:macro name="default_inertial" params="mass">
		<inertial>
			<mass value="${mass}" />
            	<inertia ixx="1.0" ixy="0.0" ixz="0.0"
                	iyy="1.0" iyz="0.0"
                    	izz="1.0" />
		</inertial>
	</xacro:macro> -->
  <gazebo>
    <plugin filename="libgazebo_ros_control.so" name="gazebo_ros_control">
      <robotNamespace>/ar600</robotNamespace>
    </plugin>
  </gazebo>
  <gazebo reference="base_link">
    <mu1>0.2</mu1>
    <mu2>0.2</mu2>
  </gazebo>
  <gazebo reference="torso">
    <mu1>0.2</mu1>
    <mu2>0.2</mu2>
  </gazebo>
  <gazebo reference="head_mount">
    <mu1>0.2</mu1>
    <mu2>0.2</mu2>
  </gazebo>
  <gazebo reference="head">
    <mu1>0.2</mu1>
    <mu2>0.2</mu2>
  </gazebo>
  <link name="base_right_hip">
    <visual>
      <geometry>
        <mesh filename="package://ar600_description/meshes/right_base_leg_low.dae"/>
      </geometry>
      <material name="white">
        <color rgba="1 1 1 1"/>
      </material>
    </visual>
    <inertial>
      <mass value="10"/>
      <inertia ixx="1.0" ixy="0.0" ixz="0.0" iyy="1.0" iyz="0.0" izz="1.0"/>
    </inertial>
    <collision>
      <geometry>
        <mesh filename="package://ar600_description/meshes/phys_model/phys_right_butt.dae"/>
      </geometry>
      <material name="white">
        <color rgba="1 1 1 1"/>
      </material>
    </collision>
  </link>
  <link name="right_hip_mount">
    <inertial>
      <mass value="1"/>
      <inertia ixx="1.0" ixy="0.0" ixz="0.0" iyy="1.0" iyz="0.0" izz="1.0"/>
    </inertial>
  </link>
  <link name="right_hip">
    <visual>
      <geometry>
        <mesh filename="package://ar600_description/meshes/right_leg_low.dae"/>
      </geometry>
      <material name="white">
        <color rgba="1 1 1 1"/>
      </material>
    </visual>
    <inertial>
      <mass value="10"/>
      <inertia ixx="1.0" ixy="0.0" ixz="0.0" iyy="1.0" iyz="0.0" izz="1.0"/>
    </inertial>
    <collision>
      <geometry>
        <mesh filename="package://ar600_description/meshes/right_leg_low.dae"/>
      </geometry>
    </collision>
  </link>
  <link name="right_shin">
    <visual>
      <geometry>
        <mesh filename="package://ar600_description/meshes/shin_low.dae"/>
      </geometry>
      <material name="white">
        <color rgba="1 1 1 1"/>
      </material>
    </visual>
    <inertial>
      <mass value="10"/>
      <inertia ixx="1.0" ixy="0.0" ixz="0.0" iyy="1.0" iyz="0.0" izz="1.0"/>
    </inertial>
    <collision>
      <geometry>
        <mesh filename="package://ar600_description/meshes/phys_model/phys_shin.dae"/>
      </geometry>
    </collision>
  </link>
  <link name="right_shin_foot_mount">
    <inertial>
      <mass value="1"/>
      <inertia ixx="1.0" ixy="0.0" ixz="0.0" iyy="1.0" iyz="0.0" izz="1.0"/>
    </inertial>
  </link>
  <link name="right_foot">
    <visual>
      <geometry>
        <mesh filename="package://ar600_description/meshes/right_foot_low.dae"/>
      </geometry>
      <material name="white">
        <color rgba="1 1 1 1"/>
      </material>
    </visual>
    <inertial>
      <mass value="10"/>
      <inertia ixx="1.0" ixy="0.0" ixz="0.0" iyy="1.0" iyz="0.0" izz="1.0"/>
    </inertial>
    <collision>
      <geometry>
        <mesh filename="package://ar600_description/meshes/right_foot_low.dae"/>
      </geometry>
    </collision>
  </link>
  <joint name="base_right_leg_joint" type="revolute">
    <parent link="base_link"/>
    <child link="base_right_hip"/>
    <origin rpy=" 0 0 0" xyz="0.05 -0.1 -0.1"/>
    <axis xyz="0 0 -1"/>
    <limit effort="1000.0" lower="1.57" upper="-1.57" velocity="0.5"/>
  </joint>
  <joint name="right_base_mount" type="revolute">
    <parent link="base_right_hip"/>
    <child link="right_hip_mount"/>
    <origin rpy=" 0 0 0" xyz="0 0.01 -.13"/>
    <limit effort="1000.0" lower="1.57" upper="-1.57" velocity="0.5"/>
    <axis xyz="-1 0 0"/>
  </joint>
  <joint name="right_base_mount_hip" type="revolute">
    <parent link="right_hip_mount"/>
    <child link="right_hip"/>
    <origin rpy="0 0 0" xyz="0 -0.02 -0.05"/>
    <limit effort="1000.0" lower="-.707" upper=".707" velocity="0.5"/>
    <axis xyz="0 -1 0"/>
  </joint>
  <joint name="right_hip_right_shin" type="revolute">
    <parent link="right_hip"/>
    <child link="right_shin"/>
    <origin rpy="0 0 0" xyz="0 0 -.3"/>
    <limit effort="1000.0" lower="0" upper="1.57" velocity="0.5"/>
    <axis xyz="0 1 0"/>
  </joint>
  <joint name="right_shin_right_foot_mount" type="revolute">
    <parent link="right_shin"/>
    <child link="right_shin_foot_mount"/>
    <origin rpy="0 0 0" xyz="0 0 -.28"/>
    <limit effort="1000.0" lower="-1.57" upper="1.57" velocity="0.5"/>
    <axis xyz="0 1 0"/>
  </joint>
  <joint name="right_shin_mount_right_foot" type="revolute">
    <parent link="right_shin_foot_mount"/>
    <child link="right_foot"/>
    <limit effort="1000.0" lower="1.57" upper="-1.57" velocity="0.5"/>
    <axis xyz="-1 0 0"/>
  </joint>
  <link name="base_left_hip">
    <visual>
      <geometry>
        <mesh filename="package://ar600_description/meshes/left_base_leg_low.dae"/>
      </geometry>
      <material name="white">
        <color rgba="1 1 1 1"/>
      </material>
    </visual>
    <inertial>
      <mass value="10"/>
      <inertia ixx="1.0" ixy="0.0" ixz="0.0" iyy="1.0" iyz="0.0" izz="1.0"/>
    </inertial>
    <collision>
      <geometry>
        <mesh filename="package://ar600_description/meshes/phys_model/phys_left_butt.dae"/>
      </geometry>
      <material name="white">
        <color rgba="1 1 1 1"/>
      </material>
    </collision>
  </link>
  <link name="left_hip_mount">
    <inertial>
      <mass value="1"/>
      <inertia ixx="1.0" ixy="0.0" ixz="0.0" iyy="1.0" iyz="0.0" izz="1.0"/>
    </inertial>
  </link>
  <link name="left_hip">
    <visual>
      <geometry>
        <mesh filename="package://ar600_description/meshes/left_leg_low.dae"/>
      </geometry>
      <material name="white">
        <color rgba="1 1 1 1"/>
      </material>
    </visual>
    <inertial>
      <mass value="10"/>
      <inertia ixx="1.0" ixy="0.0" ixz="0.0" iyy="1.0" iyz="0.0" izz="1.0"/>
    </inertial>
    <collision>
      <geometry>
        <mesh filename="package://ar600_description/meshes/left_leg_low.dae"/>
      </geometry>
    </collision>
  </link>
  <link name="left_shin">
    <visual>
      <geometry>
        <mesh filename="package://ar600_description/meshes/shin_low.dae"/>
      </geometry>
      <material name="white">
        <color rgba="1 1 1 1"/>
      </material>
    </visual>
    <inertial>
      <mass value="10"/>
      <inertia ixx="1.0" ixy="0.0" ixz="0.0" iyy="1.0" iyz="0.0" izz="1.0"/>
    </inertial>
    <collision>
      <geometry>
        <mesh filename="package://ar600_description/meshes/phys_model/phys_shin.dae"/>
      </geometry>
    </collision>
  </link>
  <link name="left_shin_foot_mount">
    <inertial>
      <mass value="1"/>
      <inertia ixx="1.0" ixy="0.0" ixz="0.0" iyy="1.0" iyz="0.0" izz="1.0"/>
    </inertial>
  </link>
  <link name="left_foot">
    <visual>
      <geometry>
        <mesh filename="package://ar600_description/meshes/left_foot_low.dae"/>
      </geometry>
      <material name="white">
        <color rgba="1 1 1 1"/>
      </material>
    </visual>
    <inertial>
      <mass value="10"/>
      <inertia ixx="1.0" ixy="0.0" ixz="0.0" iyy="1.0" iyz="0.0" izz="1.0"/>
    </inertial>
    <collision>
      <geometry>
        <mesh filename="package://ar600_description/meshes/left_foot_low.dae"/>
      </geometry>
    </collision>
  </link>
  <joint name="base_left_leg_joint" type="revolute">
    <parent link="base_link"/>
    <child link="base_left_hip"/>
    <origin rpy=" 0 0 0" xyz="0.05 0.1 -0.1"/>
    <axis xyz="0 0 1"/>
    <limit effort="1000.0" lower="-1.57" upper="1.57" velocity="0.5"/>
  </joint>
  <joint name="left_base_mount" type="revolute">
    <parent link="base_left_hip"/>
    <child link="left_hip_mount"/>
    <origin rpy=" 0 0 0" xyz="0 -0.01 -.13"/>
    <limit effort="1000.0" lower="-1.57" upper="1.57" velocity="0.5"/>
    <axis xyz="1 0 0"/>
  </joint>
  <joint name="left_base_mount_hip" type="revolute">
    <parent link="left_hip_mount"/>
    <child link="left_hip"/>
    <origin rpy="0 0 0" xyz="0 0.02 -0.05"/>
    <limit effort="1000.0" lower="-.707" upper=".707" velocity="0.5"/>
    <axis xyz="0 -1 0"/>
  </joint>
  <joint name="left_hip_left_shin" type="revolute">
    <parent link="left_hip"/>
    <child link="left_shin"/>
    <origin rpy="0 0 0" xyz="0 0 -.3"/>
    <limit effort="1000.0" lower="0" upper="1.57" velocity="0.5"/>
    <axis xyz="0 1 0"/>
  </joint>
  <joint name="left_shin_left_foot_mount" type="revolute">
    <parent link="left_shin"/>
    <child link="left_shin_foot_mount"/>
    <origin rpy="0 0 0" xyz="0 0 -.28"/>
    <limit effort="1000.0" lower="-1.57" upper="1.57" velocity="0.5"/>
    <axis xyz="0 1 0"/>
  </joint>
  <joint name="left_shin_mount_left_foot" type="revolute">
    <parent link="left_shin_foot_mount"/>
    <child link="left_foot"/>
    <limit effort="1000.0" lower="-1.57" upper="1.57" velocity="0.5"/>
    <axis xyz="1 0 0"/>
  </joint>
  <link name="right_shoulder">
    <visual>
      <geometry>
        <mesh filename="package://ar600_description/meshes/right_shoulder_low.dae"/>
      </geometry>
    </visual>
    <inertial>
      <mass value="10"/>
      <inertia ixx="1.0" ixy="0.0" ixz="0.0" iyy="1.0" iyz="0.0" izz="1.0"/>
    </inertial>
  </link>
  <link name="right_upper_forearm">
    <visual>
      <geometry>
        <mesh filename="package://ar600_description/meshes/right_upper_arm_low.dae"/>
      </geometry>
      <material name="white">
        <color rgba="1 1 1 1"/>
      </material>
    </visual>
    <inertial>
      <mass value="10"/>
      <inertia ixx="1.0" ixy="0.0" ixz="0.0" iyy="1.0" iyz="0.0" izz="1.0"/>
    </inertial>
    <collision>
      <geometry>
        <mesh filename="package://ar600_description/meshes/right_upper_arm_low.dae"/>
      </geometry>
    </collision>
  </link>
  <link name="right_elbow">
    <visual>
      <geometry>
        <mesh filename="package://ar600_description/meshes/elbow_low.dae"/>
      </geometry>
      <material name="white">
        <color rgba="1 1 1 1"/>
      </material>
    </visual>
    <inertial>
      <mass value="10"/>
      <inertia ixx="1.0" ixy="0.0" ixz="0.0" iyy="1.0" iyz="0.0" izz="1.0"/>
    </inertial>
    <collision>
      <geometry>
        <mesh filename="package://ar600_description/meshes/phys_model/phys_elbow.dae"/>
      </geometry>
    </collision>
  </link>
  <link name="right_arm">
    <visual>
      <geometry>
        <mesh filename="package://ar600_description/meshes/right_arm.dae"/>
      </geometry>
      <material name="white">
        <color rgba="1 1 1 1"/>
      </material>
    </visual>
    <inertial>
      <mass value="10"/>
      <inertia ixx="1.0" ixy="0.0" ixz="0.0" iyy="1.0" iyz="0.0" izz="1.0"/>
    </inertial>
    <collision>
      <geometry>
        <mesh filename="package://ar600_description/meshes/right_arm.dae"/>
      </geometry>
    </collision>
  </link>
  <link name="right_hand_pad">
    <visual>
      <geometry>
        <box size=".05 .05 .01"/>
      </geometry>
      <material name="white">
        <color rgba="1 1 1 1"/>
      </material>
    </visual>
    <inertial>
      <mass value="10"/>
      <inertia ixx="1.0" ixy="0.0" ixz="0.0" iyy="1.0" iyz="0.0" izz="1.0"/>
    </inertial>
    <collision>
      <geometry>
        <box size=".05 .05 .01"/>
      </geometry>
    </collision>
  </link>
  <joint name="torso_right_shoulder" type="revolute">
    <parent link="torso"/>
    <child link="right_shoulder"/>
    <origin rpy="-1.57 1.1 -1.57" xyz="-0.01 -0.11 .24"/>
    <limit effort="1000.0" lower="-0.707" upper="1.57" velocity="0.5"/>
    <axis xyz="0 -1 0"/>
  </joint>
  <joint name="right_upper_forearm_shoulder" type="revolute">
    <parent link="right_shoulder"/>
    <child link="right_upper_forearm"/>
    <origin rpy="-1.57 0 1.57" xyz="0 -0.05 0"/>
    <limit effort="1000.0" lower="0.0" upper="1.57" velocity="0.5"/>
    <axis xyz="0 1.0 0"/>
  </joint>
  <joint name="right_upper_forearm_right_lower_forearm" type="revolute">
    <parent link="right_upper_forearm"/>
    <child link="right_elbow"/>
    <origin rpy="0 0 0" xyz="0 0 -0.09"/>
    <limit effort="1000.0" lower="-1.57" upper="1.57" velocity="0.5"/>
    <axis xyz="0 0 -1"/>
  </joint>
  <joint name="right_lower_forearm_arm" type="revolute">
    <parent link="right_elbow"/>
    <child link="right_arm"/>
    <origin rpy="0 0 0" xyz="0 0 -0.1"/>
    <limit effort="1000.0" lower="-0.707" upper="0.707" velocity="0.5"/>
    <axis xyz="0 -1 0"/>
  </joint>
  <joint name="right_lower_arm_handpad" type="revolute">
    <parent link="right_arm"/>
    <child link="right_hand_pad"/>
    <origin rpy="0 0 0" xyz="0 0 -0.23"/>
    <limit effort="1000.0" lower="-0.707" upper="0.707" velocity="0.5"/>
    <axis xyz="0 0 -1"/>
  </joint>
  <link name="left_shoulder">
    <visual>
      <geometry>
        <mesh filename="package://ar600_description/meshes/left_shoulder_low.dae"/>
      </geometry>
    </visual>
    <inertial>
      <mass value="10"/>
      <inertia ixx="1.0" ixy="0.0" ixz="0.0" iyy="1.0" iyz="0.0" izz="1.0"/>
    </inertial>
  </link>
  <link name="left_upper_forearm">
    <visual>
      <geometry>
        <mesh filename="package://ar600_description/meshes/left_upper_arm_low.dae"/>
      </geometry>
      <material name="white">
        <color rgba="1 1 1 1"/>
      </material>
    </visual>
    <inertial>
      <mass value="10"/>
      <inertia ixx="1.0" ixy="0.0" ixz="0.0" iyy="1.0" iyz="0.0" izz="1.0"/>
    </inertial>
    <collision>
      <geometry>
        <mesh filename="package://ar600_description/meshes/left_upper_arm_low.dae"/>
      </geometry>
    </collision>
  </link>
  <link name="left_elbow">
    <visual>
      <geometry>
        <mesh filename="package://ar600_description/meshes/elbow_low.dae"/>
      </geometry>
      <material name="white">
        <color rgba="1 1 1 1"/>
      </material>
    </visual>
    <inertial>
      <mass value="10"/>
      <inertia ixx="1.0" ixy="0.0" ixz="0.0" iyy="1.0" iyz="0.0" izz="1.0"/>
    </inertial>
    <collision>
      <geometry>
        <mesh filename="package://ar600_description/meshes/phys_model/phys_elbow.dae"/>
      </geometry>
    </collision>
  </link>
  <link name="left_arm">
    <visual>
      <geometry>
        <mesh filename="package://ar600_description/meshes/left_arm.dae"/>
      </geometry>
      <material name="white">
        <color rgba="1 1 1 1"/>
      </material>
    </visual>
    <inertial>
      <mass value="10"/>
      <inertia ixx="1.0" ixy="0.0" ixz="0.0" iyy="1.0" iyz="0.0" izz="1.0"/>
    </inertial>
    <collision>
      <geometry>
        <mesh filename="package://ar600_description/meshes/left_arm.dae"/>
      </geometry>
    </collision>
  </link>
  <link name="left_hand_pad">
    <visual>
      <geometry>
        <box size=".05 .05 .01"/>
      </geometry>
      <material name="white">
        <color rgba="1 1 1 1"/>
      </material>
    </visual>
    <inertial>
      <mass value="10"/>
      <inertia ixx="1.0" ixy="0.0" ixz="0.0" iyy="1.0" iyz="0.0" izz="1.0"/>
    </inertial>
    <collision>
      <geometry>
        <box size=".05 .05 .01"/>
      </geometry>
    </collision>
  </link>
  <joint name="torso_left_shoulder" type="revolute">
    <parent link="torso"/>
    <child link="left_shoulder"/>
    <origin rpy="1.57 1.1 1.57" xyz="-0.01 0.11 .24"/>
    <limit effort="1000.0" lower="-0.707" upper="1.57" velocity="0.5"/>
    <axis xyz="0 -1 0"/>
  </joint>
  <joint name="left_upper_forearm_shoulder" type="revolute">
    <parent link="left_shoulder"/>
    <child link="left_upper_forearm"/>
    <origin rpy="-1.57 0 1.57" xyz="0 0.05 0"/>
    <limit effort="1000.0" lower="0.0" upper="1.57" velocity="0.5"/>
    <axis xyz="0 -1.0 0"/>
  </joint>
  <joint name="left_upper_forearm_left_lower_forearm" type="revolute">
    <parent link="left_upper_forearm"/>
    <child link="left_elbow"/>
    <origin rpy="0 0 0" xyz="0 0 -0.09"/>
    <limit effort="1000.0" lower="-1.57" upper="1.57" velocity="0.5"/>
    <axis xyz="0 0 1"/>
  </joint>
  <joint name="left_lower_forearm_arm" type="revolute">
    <parent link="left_elbow"/>
    <child link="left_arm"/>
    <origin rpy="0 0 0" xyz="0 0 -0.1"/>
    <limit effort="1000.0" lower="-0.707" upper="0.707" velocity="0.5"/>
    <axis xyz="0 -1 0"/>
  </joint>
  <joint name="left_lower_arm_handpad" type="revolute">
    <parent link="left_arm"/>
    <child link="left_hand_pad"/>
    <origin rpy="0 0 0" xyz="0 0 -0.23"/>
    <limit effort="1000.0" lower="-0.707" upper="0.707" velocity="0.5"/>
    <axis xyz="0 0 -1"/>
  </joint>
  <link name="right_palm">
    <visual>
      <geometry>
        <mesh filename="package://ar600_description/meshes/right_palm.dae"/>
      </geometry>
      <material name="white">
        <color rgba="1 1 1 1"/>
      </material>
    </visual>
    <inertial>
      <mass value="0.1"/>
      <inertia ixx="1.0" ixy="0.0" ixz="0.0" iyy="1.0" iyz="0.0" izz="1.0"/>
    </inertial>
    <collision>
      <geometry>
        <mesh filename="package://ar600_description/meshes/right_palm.dae"/>
      </geometry>
    </collision>
  </link>
  <!-- <link name="${prefix}bigfingerseg1">
		<visual>
			<xacro:box_shape size=".02 .01 .03"/>
			<origin xyz="0 0 -0.015" rpy="0 0 0"/>			
			<xacro:white_material/>
		</visual>
		<inertial>s
			<mass value="0.05"/>
			<inertia ixx="1.0" ixy="0.0" ixz="0.0" iyy="1.0" iyz="0.0" izz="1.0"/>
		</inertial>
		<collision>
			<xacro:box_shape size=".02 .01 .03"/>
			<origin xyz="0 0 -0.015" rpy="0 0 0"/>
		</collision>
	</link>



	<link name="${prefix}bigfingerseg2">
		<visual>
			<xacro:box_shape size=".02 .01 .03"/>
			<origin xyz="0 0 -0.015" rpy="0 0 0"/>
			<xacro:white_material/>
		</visual>
		<inertial>
			<mass value="0.05"/>
			<inertia ixx="1.0" ixy="0.0" ixz="0.0" iyy="1.0" iyz="0.0" izz="1.0"/>
		</inertial>
		<collision>
			<xacro:box_shape size=".02 .01 .03"/>
			<origin xyz="0 0 -0.015" rpy="0 0 0"/>
		</collision>
	</link>

	<link name="${prefix}bigfingerseg3">
		<visual>
			<xacro:box_shape size=".02 .01 .02"/>
			<origin xyz="0 0 -0.01" rpy="0 0 0"/>
			<xacro:white_material/>
		</visual>
		<inertial>
			<mass value="0.05"/>
			<inertia ixx="1.0" ixy="0.0" ixz="0.0" iyy="1.0" iyz="0.0" izz="1.0"/>
		</inertial>
		<collision>
			<xacro:box_shape size=".01 .01 .01"/>
			<origin xyz="0 0 -0.005" rpy="0 0 0"/>
		</collision>
	</link> -->
  <joint name="right_arm_right_palm" type="fixed">
    <parent link="right_hand_pad"/>
    <child link="right_palm"/>
    <origin rpy="0 0 0" xyz="0 0 0.01"/>
  </joint>
  <joint name="right_palm_thumb1" type="revolute">
    <parent link="right_palm"/>
    <child link="rightbigfingerseg1"/>
    <origin rpy="0 0 0" xyz="0.02 -0.025 -0.04"/>
    <limit effort="1000.0" lower="-0.5" upper="0.707" velocity="0.5"/>
    <axis xyz="0 1.0 0"/>
    <dynamics damping="20000.0"/>
  </joint>
  <joint name="right_thumb1_thumb2" type="revolute">
    <parent link="rightbigfingerseg1"/>
    <child link="rightbigfingerseg2"/>
    <origin rpy="0 0 0" xyz="0 0 -0.03"/>
    <limit effort="1000.0" lower="0" upper="0.707" velocity="0.5"/>
    <axis xyz="0 1.0 0"/>
    <dynamics damping="20000.0"/>
  </joint>
  <joint name="right_thumb2_thumb3" type="revolute">
    <parent link="rightbigfingerseg2"/>
    <child link="rightbigfingerseg3"/>
    <origin rpy="0 0 0" xyz="0 0 -0.02"/>
    <limit effort="1000.0" lower="0" upper="0.707" velocity="0.5"/>
    <axis xyz="0 1.0 0"/>
    <dynamics damping="20000.0"/>
  </joint>
  <link name="left_palm">
    <visual>
      <geometry>
        <mesh filename="package://ar600_description/meshes/left_palm.dae"/>
      </geometry>
      <material name="white">
        <color rgba="1 1 1 1"/>
      </material>
    </visual>
    <inertial>
      <mass value="0.1"/>
      <inertia ixx="1.0" ixy="0.0" ixz="0.0" iyy="1.0" iyz="0.0" izz="1.0"/>
    </inertial>
    <collision>
      <geometry>
        <mesh filename="package://ar600_description/meshes/left_palm.dae"/>
      </geometry>
    </collision>
  </link>
  <!-- <link name="${prefix}bigfingerseg1">
		<visual>
			<xacro:box_shape size=".02 .01 .03"/>
			<origin xyz="0 0 -0.015" rpy="0 0 0"/>			
			<xacro:white_material/>
		</visual>
		<inertial>s
			<mass value="0.05"/>
			<inertia ixx="1.0" ixy="0.0" ixz="0.0" iyy="1.0" iyz="0.0" izz="1.0"/>
		</inertial>
		<collision>
			<xacro:box_shape size=".02 .01 .03"/>
			<origin xyz="0 0 -0.015" rpy="0 0 0"/>
		</collision>
	</link>



	<link name="${prefix}bigfingerseg2">
		<visual>
			<xacro:box_shape size=".02 .01 .03"/>
			<origin xyz="0 0 -0.015" rpy="0 0 0"/>
			<xacro:white_material/>
		</visual>
		<inertial>
			<mass value="0.05"/>
			<inertia ixx="1.0" ixy="0.0" ixz="0.0" iyy="1.0" iyz="0.0" izz="1.0"/>
		</inertial>
		<collision>
			<xacro:box_shape size=".02 .01 .03"/>
			<origin xyz="0 0 -0.015" rpy="0 0 0"/>
		</collision>
	</link>

	<link name="${prefix}bigfingerseg3">
		<visual>
			<xacro:box_shape size=".02 .01 .02"/>
			<origin xyz="0 0 -0.01" rpy="0 0 0"/>
			<xacro:white_material/>
		</visual>
		<inertial>
			<mass value="0.05"/>
			<inertia ixx="1.0" ixy="0.0" ixz="0.0" iyy="1.0" iyz="0.0" izz="1.0"/>
		</inertial>
		<collision>
			<xacro:box_shape size=".01 .01 .01"/>
			<origin xyz="0 0 -0.005" rpy="0 0 0"/>
		</collision>
	</link> -->
  <joint name="left_arm_left_palm" type="fixed">
    <parent link="left_hand_pad"/>
    <child link="left_palm"/>
    <origin rpy="0 0 0" xyz="0 0 0.01"/>
  </joint>
  <joint name="left_palm_thumb1" type="revolute">
    <parent link="left_palm"/>
    <child link="leftbigfingerseg1"/>
    <origin rpy="0 0 0" xyz="-0.02 -0.025 -0.04"/>
    <limit effort="1000.0" lower="-0.5" upper="0.707" velocity="0.5"/>
    <axis xyz="0 -1.0 0"/>
    <dynamics damping="20000.0"/>
  </joint>
  <joint name="left_thumb1_thumb2" type="revolute">
    <parent link="leftbigfingerseg1"/>
    <child link="leftbigfingerseg2"/>
    <origin rpy="0 0 0" xyz="0 0 -0.03"/>
    <limit effort="1000.0" lower="0" upper="0.707" velocity="0.5"/>
    <axis xyz="0 -1.0 0"/>
    <dynamics damping="20000.0"/>
  </joint>
  <joint name="left_thumb2_thumb3" type="revolute">
    <parent link="leftbigfingerseg2"/>
    <child link="leftbigfingerseg3"/>
    <origin rpy="0 0 0" xyz="0 0 -0.02"/>
    <limit effort="1000.0" lower="0" upper="0.707" velocity="0.5"/>
    <axis xyz="0 -1.0 0"/>
    <dynamics damping="20000.0"/>
  </joint>
  <!-- 	<xacro:macro name="box_shape" params="size">
		<geometry>
			<box size="${size}"/>	
		</geometry>		
	</xacro:macro> -->
  <!-- 	<xacro:macro name="cylinder_shape" params="radius length">
		<geometry>
			<cylinder radius="${radius}" length="${length}"/>	
		</geometry>		
	</xacro:macro> -->
  <link name="base_link">
    <visual>
      <geometry>
        <mesh filename="package://ar600_description/meshes/base_low.dae"/>
      </geometry>
    </visual>
    <inertial>
      <mass value="10"/>
      <inertia ixx="1.0" ixy="0.0" ixz="0.0" iyy="1.0" iyz="0.0" izz="1.0"/>
    </inertial>
    <collision>
      <geometry>
        <mesh filename="package://ar600_description/meshes/phys_model/phys_base.dae"/>
      </geometry>
    </collision>
  </link>
  <link name="torso">
    <visual>
      <geometry>
        <mesh filename="package://ar600_description/meshes/body_low.dae"/>
      </geometry>
      <material name="white">
        <color rgba="1 1 1 1"/>
      </material>
    </visual>
    <inertial>
      <mass value="10"/>
      <inertia ixx="1.0" ixy="0.0" ixz="0.0" iyy="1.0" iyz="0.0" izz="1.0"/>
    </inertial>
    <collision>
      <geometry>
        <mesh filename="package://ar600_description/meshes/body_low.dae"/>
      </geometry>
    </collision>
  </link>
  <link name="head_mount">
    <inertial>
      <mass value="1"/>
      <inertia ixx="1.0" ixy="0.0" ixz="0.0" iyy="1.0" iyz="0.0" izz="1.0"/>
    </inertial>
  </link>
  <link name="head">
    <visual>
      <geometry>
        <mesh filename="package://ar600_description/meshes/head_low.dae"/>
      </geometry>
      <material name="white">
        <color rgba="1 1 1 1"/>
      </material>
    </visual>
    <inertial>
      <mass value="10"/>
      <inertia ixx="1.0" ixy="0.0" ixz="0.0" iyy="1.0" iyz="0.0" izz="1.0"/>
    </inertial>
    <collision>
      <geometry>
        <mesh filename="package://ar600_description/meshes/head_low.dae"/>
      </geometry>
      <material name="white">
        <color rgba="1 1 1 1"/>
      </material>
    </collision>
  </link>
  <joint name="base_torso" type="continuous">
    <parent link="base_link"/>
    <child link="torso"/>
    <origin rpy="0 0 0" xyz="0.05 0 0"/>
    <limit effort="1000.0" lower="0.0" upper="0.548" velocity="0.5"/>
    <axis xyz="0 0 1"/>
    <dynamics damping="0.7"/>
  </joint>
  <joint name="torso_head_mount" type="revolute">
    <parent link="torso"/>
    <child link="head_mount"/>
    <origin rpy="0 0 0" xyz="-0.05 0 .34"/>
    <limit effort="1000.0" lower="0.0" upper="0.548" velocity="0.5"/>
    <axis xyz="0 0 1"/>
    <dynamics damping="0.7"/>
  </joint>
  <joint name="head_mount_head" type="revolute">
    <parent link="head_mount"/>
    <child link="head"/>
    <limit effort="1000.0" lower="-.5" upper=".5" velocity="0.5"/>
    <axis xyz="0 1 0"/>
    <dynamics damping="0.7"/>
  </joint>
  <transmission name="tran1">
    <type>transmission_interface/SimpleTransmission</type>
    <joint name="base_torso"/>
    <actuator name="motor1">
      <hardwareInterface>EffortJointInterface</hardwareInterface>
      <mechanicalReduction>1</mechanicalReduction>
    </actuator>
  </transmission>
  <!-- <xacro:include filename="low_finger.xacro.xml"/> -->
</robot>
