<robot xmlns:xacro="http://www.ros.org/wiki/xacro"  name="ar600">


	<xacro:macro name="box_shape" params="size">
		<geometry>
			<box size="${size}"/>	
		</geometry>		
	</xacro:macro>

	<xacro:macro name="white_material">
				<material name="white">
					<color rgba="1 1 1 1"/>
				</material>
	</xacro:macro>

	<xacro:macro name="hand" params="prefix reflect">
	<link name="${prefix}_shoulder">
		<visual>
			<geometry>				
				<mesh filename="package://ar600_description/meshes/${prefix}_shoulder_low.dae"/>
			</geometry>
		</visual>		
		<inertial>
			<mass value="10"/>
			<inertia ixx="1.0" ixy="0.0" ixz="0.0" iyy="1.0" iyz="0.0" izz="1.0"/>
		</inertial>			

	</link>

	<link name="${prefix}_upper_forearm">
		<visual>
			<geometry>
				<mesh filename="package://ar600_description/meshes/${prefix}_upper_arm_low.dae"/>
			</geometry>		
			<xacro:white_material/>
		</visual>
		<inertial>
			<mass value="10"/>
			<inertia ixx="1.0" ixy="0.0" ixz="0.0" iyy="1.0" iyz="0.0" izz="1.0"/>
		</inertial>			
		
		<collision>
			<geometry>
				<mesh filename="package://ar600_description/meshes/${prefix}_upper_arm_low.dae"/>
			</geometry>		
					</collision>	
	</link>



	<link name="${prefix}_elbow">
		<visual>
			<geometry>
				<mesh filename="package://ar600_description/meshes/elbow_low.dae"/>
			</geometry>		
			
			<xacro:white_material/>
		</visual>
		<inertial>
			<mass value="10"/>
			<inertia ixx="1.0" ixy="0.0" ixz="0.0" iyy="1.0" iyz="0.0" izz="1.0"/>
		</inertial>			
		
		<collision>
			<geometry>
				<mesh filename="package://ar600_description/meshes/phys_model/phys_elbow.dae"/>
			</geometry>		
		</collision>	
	</link>

	<link name="${prefix}_arm">
		<visual>			
			<geometry>
				<mesh filename="package://ar600_description/meshes/${prefix}_arm.dae"/>
			</geometry>		
			<xacro:white_material/>			
		</visual>
		<inertial>
			<mass value="10"/>
			<inertia ixx="1.0" ixy="0.0" ixz="0.0" iyy="1.0" iyz="0.0" izz="1.0"/>
		</inertial>					
		<collision>
			<geometry>
				<mesh filename="package://ar600_description/meshes/${prefix}_arm.dae"/>
			</geometry>		
		</collision>	
	</link>


	<link name="${prefix}_hand_pad">
				<visual>			
			<geometry>
				<box size=".05 .05 .01"/>
			</geometry>		
			<xacro:white_material/>			
		</visual>
		<inertial>
			<mass value="10"/>
			<inertia ixx="1.0" ixy="0.0" ixz="0.0" iyy="1.0" iyz="0.0" izz="1.0"/>
		</inertial>					
		<collision>
			<geometry>
			
				<box size=".05 .05 .01"/>
			
			</geometry>		
		</collision>	
	</link>


	<joint name="torso_${prefix}_shoulder" type="revolute">
		<parent link="torso"/>
		<child link="${prefix}_shoulder"/>
		<origin xyz="-0.01 ${0.11*reflect} .24" rpy="${reflect*1.57} 1.1 ${1.57*reflect}"/>
		<limit effort="1000.0" lower="-0.707" upper="1.57" velocity="0.5"/>
		<axis xyz="0 -1 0"/>
	</joint>

	<joint name="${prefix}_upper_forearm_shoulder" type="revolute">
		<parent link="${prefix}_shoulder"/>
		<child link="${prefix}_upper_forearm"/>
		<origin xyz="0 ${.05*reflect} 0" rpy="-1.57 0 1.57"/>
		<limit effort="1000.0" lower="0.0" upper="1.57" velocity="0.5"/>
		<axis xyz="0 ${-1 * reflect} 0"/>
	</joint>


	<joint name="${prefix}_upper_forearm_${prefix}_lower_forearm" type="revolute">
		<parent link="${prefix}_upper_forearm"/>
		<child link="${prefix}_elbow"/>
		<origin xyz="0 0 -0.09" rpy="0 0 0"/>
		<limit effort="1000.0" lower="-1.57" upper="1.57" velocity="0.5"/>
		<axis xyz="0 0 ${reflect}"/>
	</joint>

	<joint name="${prefix}_lower_forearm_arm" type="revolute">
		<parent link="${prefix}_elbow"/>
		<child link="${prefix}_arm"/>
		<origin xyz="0 0 -0.1" rpy="0 0 0"/>
		<limit effort="1000.0" lower="-0.707" upper="0.707" velocity="0.5"/>
		<axis xyz="0 -1 0"/>
	</joint>

	<joint name="${prefix}_lower_arm_handpad" type="revolute">
		<parent link="${prefix}_arm"/>
		<child link="${prefix}_hand_pad"/>
		<origin xyz="0 0 -0.23" rpy="0 0 0"/>		
		<limit effort="1000.0" lower="-0.707" upper="0.707" velocity="0.5"/>
		<axis xyz="0 0 -1"/>
	</joint>

	</xacro:macro>

     
	<xacro:hand prefix="right" reflect="-1"/>
	<xacro:hand prefix="left" reflect="1"/>

</robot>
