<robot xmlns:xacro="http://www.ros.org/wiki/xacro" name="ar600">

	<xacro:macro name="box_shape" params="size">
		<geometry>
			<box size="${size}"/>	
		</geometry>		
	</xacro:macro>

	<xacro:macro name="white_material">
				<material name="white">
					<color rgba="1 1 1 1"/>
				</material>
	</xacro:macro>

	<xacro:macro name="leg" params="prefix reflect">
		<link name="base_${prefix}_hip">
		<visual>
			<geometry>
				<mesh filename="package://ar600_description/meshes/${prefix}_base_leg_low.dae"/>
			</geometry>
			
			<xacro:white_material/>
		</visual>	
		<inertial>
			<mass value="10"/>
			<inertia ixx="1.0" ixy="0.0" ixz="0.0" iyy="1.0" iyz="0.0" izz="1.0"/>
		</inertial>			
		
		<collision>
			<geometry>
				<mesh filename="package://ar600_description/meshes/phys_model/phys_${prefix}_butt.dae"/>
			</geometry>
			
			<xacro:white_material/>
		</collision>	

	</link>

	<link name="${prefix}_hip_mount">		
				<inertial>
			<mass value="1"/>
			<inertia ixx="1.0" ixy="0.0" ixz="0.0" iyy="1.0" iyz="0.0" izz="1.0"/>
		</inertial>			

	</link>


	<link name="${prefix}_hip">
		<visual>
			<geometry>
				<mesh filename="package://ar600_description/meshes/${prefix}_leg_low.dae"/>
			</geometry>		

			<xacro:white_material/>
		</visual>
		<inertial>
			<mass value="10"/>
			<inertia ixx="1.0" ixy="0.0" ixz="0.0" iyy="1.0" iyz="0.0" izz="1.0"/>
		</inertial>			
		
		<collision>
			<geometry>
				<mesh filename="package://ar600_description/meshes/${prefix}_leg_low.dae"/>
			</geometry>		
		</collision>	

	</link>
	<link name="${prefix}_shin">
		<visual>
			<geometry>
				<mesh filename="package://ar600_description/meshes/shin_low.dae"/>
			</geometry>		
			
			<xacro:white_material/>
		</visual>
		<inertial>
			<mass value="10"/>
			<inertia ixx="1.0" ixy="0.0" ixz="0.0" iyy="1.0" iyz="0.0" izz="1.0"/>
		</inertial>			
		
		<collision>
						<geometry>
				<mesh filename="package://ar600_description/meshes/phys_model/phys_shin.dae"/>
			</geometry>
			
		</collision>	

	</link>

	<link name="${prefix}_shin_foot_mount">
		<inertial>
			<mass value="1"/>
			<inertia ixx="1.0" ixy="0.0" ixz="0.0" iyy="1.0" iyz="0.0" izz="1.0"/>
		</inertial>			

	</link>
	
	<link name="${prefix}_foot">
		<visual>
			<geometry>				
				<mesh filename="package://ar600_description/meshes/${prefix}_foot_low.dae"/>
			</geometry>
		<xacro:white_material/>
		</visual>
		<inertial>
			<mass value="10"/>
			<inertia ixx="1.0" ixy="0.0" ixz="0.0" iyy="1.0" iyz="0.0" izz="1.0"/>
		</inertial>			
		
		<collision>
			<geometry>
				<mesh filename="package://ar600_description/meshes/${prefix}_foot_low.dae"/>
			</geometry>
		</collision>	
	</link>
	
	<joint name="base_${prefix}_leg_joint" type="revolute">
		<parent link="base_link"/>
		<child link="base_${prefix}_hip"/>
		<origin xyz="0.05 ${.1*reflect} -0.1" rpy=" 0 0 0"/>
		<axis xyz="0 0 ${reflect}"/>	
		<limit effort="1000.0" lower="${-1.57*reflect}" upper="${1.57*reflect}" velocity="0.5"/>
	</joint>

	<joint	name="${prefix}_base_mount" type="revolute">
		<parent link="base_${prefix}_hip"/>
		<child link="${prefix}_hip_mount"/>
		<origin xyz="0 ${-.01*reflect} -.13" rpy=" 0 0 0"/>
		<limit effort="1000.0" lower="${-1.57*reflect}" upper="${1.57*reflect}" velocity="0.5"/>
		<axis xyz="${reflect} 0 0"/>
	</joint>
	
	<joint	name="${prefix}_base_mount_hip" type="revolute">
		<parent link="${prefix}_hip_mount"/>
		<child link="${prefix}_hip"/>
		<origin xyz="0 ${.02*reflect} -0.05" rpy="0 0 0"/>
		<limit effort="1000.0" lower="-.707" upper=".707" velocity="0.5"/>
		<axis xyz="0 -1 0"/>
	</joint>	 

	<joint name="${prefix}_hip_${prefix}_shin" type="revolute">
		<parent link="${prefix}_hip"/>
		<child link="${prefix}_shin"/>
		<origin xyz="0 0 -.3" rpy="0 0 0"/>
		<limit effort="1000.0" lower="0" upper="1.57" velocity="0.5"/>
		<axis xyz="0 1 0"/>
	</joint>

	<joint name="${prefix}_shin_${prefix}_foot_mount" type="revolute">
		<parent link="${prefix}_shin"/>
		<child link="${prefix}_shin_foot_mount"/>
		<origin xyz="0 0 -.28" rpy="0 0 0"/>
		<limit effort="1000.0" lower="-1.57" upper="1.57" velocity="0.5"/>
		<axis xyz="0 1 0"/>
	</joint>

	<joint name="${prefix}_shin_mount_${prefix}_foot" type="revolute">
		<parent link="${prefix}_shin_foot_mount"/>
		<child link="${prefix}_foot"/>
		<limit effort="1000.0" lower="${-1.57*reflect}" upper="${1.57*reflect}" velocity="0.5"/>
		<axis xyz="${reflect} 0 0"/>
	</joint>

	</xacro:macro>

	<xacro:leg prefix="right" reflect="-1"/>
	<xacro:leg prefix="left" reflect="1"/>
</robot>