<?xml version="1.0"?>
<robot xmlns:xacro="http://ros.org/wiki/xacro">
	
  	<xacro:include filename="$(find ar600_description)/urdf/base/base.gazebo.xacro" />
  	<xacro:include filename="$(find ar600_description)/urdf/base/base.transmission.xacro" />

	<xacro:macro name="ar600_body_macro" params="name">
		<link name="${name}_link">		
			<inertial>
				<mass value="10"/>
				<inertia 
					 ixx="1.0" ixy="0.0" ixz="0.0" 
					 		   iyy="1.0" iyz="0.0" 
					                     izz="1.0"
				/>
			</inertial>	
			<collision>
				<geometry>
					<mesh filename="package://ar600_description/meshes/base.stl"/>
				</geometry>			
			</collision>
			<visual>
				<geometry>
					<mesh filename="package://ar600_description/meshes/base_low.dae"/>
				</geometry>					
			</visual>			
		</link>
		
		<link name="torso_link">
			<inertial>
				<mass value="30"/>
				<inertia 
					 ixx="1.0" ixy="0.0" ixz="0.0" 
					 	       iyy="1.0" iyz="0.0" 
					                     izz="1.0"
				/>
			</inertial>	
			<collision>
				<geometry>
					<mesh filename="package://ar600_description/meshes/body.stl"/>
				</geometry>			
			</collision>
			<visual>
				<geometry>
					<mesh filename="package://ar600_description/meshes/body.dae"/>
				</geometry>					
			</visual>
		</link>

	 	<joint name="torso_rotation_joint" type="revolute">
				<axis xyz="0 0 1" />				      							
				<dynamics damping="0.7" />
				<parent link="${name}_link"/>
				<child link="torso_link"/>
				<limit effort="1000.0" lower="-.5" upper=".5" velocity="0.5"/>
				<origin xyz="0 0 0" rpy="0 0 0"/>				
    	</joint>

		<xacro:ar600_base_gazebo name="${name}"/>
		<xacro:ar600_torso_gazebo name="${name}"/>
    	<xacro:ar600_base_torso_transmission/>
	</xacro:macro>

</robot>
