<?xml version="1.0" ?>
<!-- =================================================================================== -->
<!-- |    This document was autogenerated by xacro from ar600.head.urdf.xacro          | -->
<!-- |    EDITING THIS FILE BY HAND IS NOT RECOMMENDED                                 | -->
<!-- =================================================================================== -->
<robot name="ar600_torso" xmlns:controller="http://playerstage.sourceforge.net/gazebo/xmlschema/#controller" xmlns:interface="http://playerstage.sourceforge.net/gazebo/xmlschema/#interface" xmlns:sensor="http://playerstage.sourceforge.net/gazebo/xmlschema/#sensor" xmlns:xacro="http://ros.org/wiki/xacro">
  <plugin filename="libgazebo_ros_controller_manager.so" name="gazebo_ros_controller_manager">
    <alwaysOn>true</alwaysOn>
    <updateRate>1000.0</updateRate>
  </plugin>
  <link name="base_link">
    <inertial>
      <mass value="10"/>
      <inertia ixx="1.0" ixy="0.0" ixz="0.0" iyy="1.0" iyz="0.0" izz="1.0"/>
    </inertial>
    <collision>
      <geometry>
        <mesh filename="package://ar600_description/meshes/base.stl"/>
      </geometry>
    </collision>
    <visual>
      <geometry>
        <mesh filename="package://ar600_description/meshes/base_low.dae"/>
      </geometry>
    </visual>
  </link>
  <link name="torso_link">
    <inertial>
      <mass value="10"/>
      <inertia ixx="1.0" ixy="0.0" ixz="0.0" iyy="1.0" iyz="0.0" izz="1.0"/>
    </inertial>
    <collision>
      <geometry>
        <mesh filename="package://ar600_description/meshes/body.stl"/>
      </geometry>
    </collision>
    <visual>
      <geometry>
        <mesh filename="package://ar600_description/meshes/body.dae"/>
      </geometry>
    </visual>
  </link>
  <joint name="torso_rotation_joint" type="continuous">
    <axis xyz="0 0 1"/>
    <dynamics damping="20000.0"/>
    <parent link="base_link"/>
    <child link="torso_link"/>
    <origin rpy="0 0 0" xyz="0 0 0"/>
  </joint>
  <transmission name="torso_rotation_trans" type="transmission_interface/SimpleTransmission">
    <actuator name="torso_rotation_motor"/>
    <joint name="torso_rotation_joint"/>
    <mechanicalReduction>-79.2380952381</mechanicalReduction>
  </transmission>
  <!-- 	<link name="base_link">
		<inertial>
			<mass value="10"/>
			<inertia ixx="1.0" ixy="0.0" ixz="0.0" iyy="1.0" iyz="0.0" izz="1.0"/>
		</inertial>	
	</link> -->
  <link name="head_link">
    <visual>
      <geometry>
        <mesh filename="package://ar600_description/meshes/head_low.dae"/>
      </geometry>
    </visual>
    <inertial>
      <mass value="10"/>
      <inertia ixx="1.0" ixy="0.0" ixz="0.0" iyy="1.0" iyz="0.0" izz="1.0"/>
    </inertial>
    <collision>
      <geometry>
        <mesh filename="package://ar600_description/meshes/phys_model/head.stl"/>
      </geometry>
    </collision>
  </link>
  <link name="head_mount">
    <inertial>
      <mass value="1"/>
      <inertia ixx="1.0" ixy="0.0" ixz="0.0" iyy="1.0" iyz="0.0" izz="1.0"/>
    </inertial>
  </link>
  <joint name="torso_head_mount" type="revolute">
    <parent link="base_link"/>
    <child link="head_mount"/>
    <origin rpy="0 0 0" xyz="-0.05 0 .37"/>
    <limit effort="1000.0" lower="0.0" upper="0.548" velocity="0.5"/>
    <axis xyz="0 0 1"/>
    <dynamics damping="20000.0"/>
  </joint>
  <joint name="head_mount_head" type="revolute">
    <parent link="head_mount"/>
    <child link="head_link"/>
    <limit effort="1000.0" lower="-.5" upper=".5" velocity="0.5"/>
    <axis xyz="0 1 0"/>
    <dynamics damping="20000.0"/>
    <origin rpy="0 0 0" xyz="0 0 0"/>
  </joint>
</robot>

