<?xml version="1.0" ?>
<!-- =================================================================================== -->
<!-- |    This document was autogenerated by xacro from ar600.hand.urdf.xacro          | -->
<!-- |    EDITING THIS FILE BY HAND IS NOT RECOMMENDED                                 | -->
<!-- =================================================================================== -->
<robot name="ar600_hand" xmlns:controller="http://playerstage.sourceforge.net/gazebo/xmlschema/#controller" xmlns:interface="http://playerstage.sourceforge.net/gazebo/xmlschema/#interface" xmlns:sensor="http://playerstage.sourceforge.net/gazebo/xmlschema/#sensor" xmlns:xacro="http://ros.org/wiki/xacro">
  <gazebo>
    <plugin filename="libgazebo_ros_control.so" name="gazebo_ros_control">
      <robotNamespace>/ar600</robotNamespace>
    </plugin>
    <plugin filename="libgazebo_ros_controller_manager.so" name="gazebo_ros_controller_manager">
      <alwaysOn>true</alwaysOn>
      <updateRate>1000.0</updateRate>
      <robotNamespace>/ar600</robotNamespace>
    </plugin>
  </gazebo>
  <link name="base_link">
    <inertial>
      <mass value="10"/>
      <inertia ixx="1.0" ixy="0.0" ixz="0.0" iyy="1.0" iyz="0.0" izz="1.0"/>
    </inertial>
  </link>
  <link name="left_shoulder">
    <visual>
      <geometry>
        <mesh filename="package://ar600_description/meshes/left_shoulder_low.dae"/>
      </geometry>
    </visual>
    <inertial>
      <mass value="1"/>
      <inertia ixx="1.0" ixy="0.0" ixz="0.0" iyy="1.0" iyz="0.0" izz="1.0"/>
    </inertial>
  </link>
  <link name="left_upper_forearm">
    <visual>
      <geometry>
        <mesh filename="package://ar600_description/meshes/left_upper_arm_high.dae"/>
      </geometry>
    </visual>
    <inertial>
      <mass value="4"/>
      <inertia ixx="1.0" ixy="0.0" ixz="0.0" iyy="1.0" iyz="0.0" izz="1.0"/>
    </inertial>
    <collision>
      <geometry>
        <mesh filename="package://ar600_description/meshes/phys_model/forearm.stl"/>
      </geometry>
    </collision>
  </link>
  <link name="left_elbow">
    <visual>
      <geometry>
        <mesh filename="package://ar600_description/meshes/elbow_low.dae"/>
      </geometry>
    </visual>
    <inertial>
      <mass value="1"/>
      <inertia ixx="1.0" ixy="0.0" ixz="0.0" iyy="1.0" iyz="0.0" izz="1.0"/>
    </inertial>
    <collision>
      <geometry>
        <mesh filename="package://ar600_description/meshes/phys_model/elbow.stl"/>
      </geometry>
    </collision>
  </link>
  <link name="left_arm_link">
    <visual>
      <geometry>
        <mesh filename="package://ar600_description/meshes/left_arm.dae"/>
      </geometry>
    </visual>
    <inertial>
      <mass value="3"/>
      <inertia ixx="1.0" ixy="0.0" ixz="0.0" iyy="1.0" iyz="0.0" izz="1.0"/>
    </inertial>
    <collision>
      <geometry>
        <mesh filename="package://ar600_description/meshes/phys_model/arm.stl"/>
      </geometry>
    </collision>
  </link>
  <link name="left_hand_effector_link">
    <inertial>
      <mass value=".1"/>
      <inertia ixx="1.0" ixy="0.0" ixz="0.0" iyy="1.0" iyz="0.0" izz="1.0"/>
    </inertial>
  </link>
  <joint name="torso_left_shoulder" type="revolute">
    <parent link="base_link"/>
    <child link="left_shoulder"/>
    <origin rpy="0 0 1.57" xyz="0 0 0"/>
    <limit effort="1000.0" lower="-0.707" upper="1.57" velocity="0.5"/>
    <axis xyz="0 -1 0"/>
    <dynamics damping="20000.0"/>
  </joint>
  <joint name="left_upper_forearm_shoulder" type="revolute">
    <parent link="left_shoulder"/>
    <child link="left_upper_forearm"/>
    <origin rpy="-1.57 0 1.57" xyz="0 0.055 0"/>
    <limit effort="1000.0" lower="0.0" upper="1.57" velocity="0.5"/>
    <axis xyz="0 -1.0 0"/>
    <dynamics damping="20000.0"/>
  </joint>
  <joint name="left_upper_forearm_left_lower_forearm" type="revolute">
    <parent link="left_upper_forearm"/>
    <child link="left_elbow"/>
    <origin rpy="0 0 0" xyz="0 0 -0.12"/>
    <limit effort="1000.0" lower="-1.57" upper="1.57" velocity="0.5"/>
    <axis xyz="0 0 1"/>
    <dynamics damping="20000.0"/>
  </joint>
  <joint name="left_lower_forearm_arm" type="revolute">
    <parent link="left_elbow"/>
    <child link="left_arm_link"/>
    <origin rpy="0 0 0" xyz="0 0 -0.1"/>
    <limit effort="1000.0" lower="0" upper="1.57" velocity="0.5"/>
    <axis xyz="-1 0 0"/>
    <dynamics damping="20000.0"/>
  </joint>
  <joint name="left_lower_arm_effector" type="revolute">
    <parent link="left_arm_link"/>
    <child link="left_hand_effector_link"/>
    <limit effort="1000.0" lower="-0.707" upper="0.707" velocity="0.5"/>
    <origin rpy="0 0 0" xyz="0.005 0.005 -0.21"/>
    <axis xyz="0 0 -1"/>
    <dynamics damping="20000.0"/>
  </joint>
  <link name="left_palm">
    <visual>
      <geometry>
        <mesh filename="package://ar600_description/meshes/left_palm_vis.dae"/>
      </geometry>
    </visual>
    <inertial>
      <mass value="0.1"/>
      <inertia ixx="1.0" ixy="0.0" ixz="0.0" iyy="1.0" iyz="0.0" izz="1.0"/>
    </inertial>
    <collision>
      <geometry>
        <mesh filename="package://ar600_description/meshes/left_palm.stl"/>
      </geometry>
    </collision>
  </link>
  <link name="leftbigfingerseg1">
    <visual>
      <geometry>
        <mesh filename="package://ar600_description/meshes/finger_segment.dae"/>
      </geometry>
    </visual>
    <inertial>
      <mass value="0.05"/>
      <inertia ixx="1.0" ixy="0.0" ixz="0.0" iyy="1.0" iyz="0.0" izz="1.0"/>
    </inertial>
    <collision>
      <geometry>
        <mesh filename="package://ar600_description/meshes/finger_segment.stl"/>
      </geometry>
    </collision>
  </link>
  <link name="leftbigfingerseg2">
    <visual>
      <geometry>
        <mesh filename="package://ar600_description/meshes/finger_segment.dae"/>
      </geometry>
    </visual>
    <inertial>
      <mass value="0.05"/>
      <inertia ixx="1.0" ixy="0.0" ixz="0.0" iyy="1.0" iyz="0.0" izz="1.0"/>
    </inertial>
    <collision>
      <geometry>
        <mesh filename="package://ar600_description/meshes/finger_segment.stl"/>
      </geometry>
    </collision>
  </link>
  <link name="leftbigfingerseg3">
    <visual>
      <geometry>
        <mesh filename="package://ar600_description/meshes/finger_tip.dae"/>
      </geometry>
    </visual>
    <inertial>
      <mass value="0.05"/>
      <inertia ixx="1.0" ixy="0.0" ixz="0.0" iyy="1.0" iyz="0.0" izz="1.0"/>
    </inertial>
    <collision>
      <geometry>
        <mesh filename="package://ar600_description/meshes/finger_segment.stl"/>
      </geometry>
    </collision>
  </link>
  <joint name="arm_left_palm" type="revolute">
    <parent link="left_hand_effector_link"/>
    <child link="left_palm"/>
    <origin rpy="0 0 -1.57" xyz="0 0 0"/>
    <limit effort="1000.0" lower="-0.707" upper="0.707" velocity="0.5"/>
    <axis xyz="0 0 -1.0"/>
    <dynamics damping="0.7"/>
  </joint>
  <joint name="left_palm_thumb1" type="fixed">
    <parent link="left_palm"/>
    <child link="leftbigfingerseg1"/>
    <origin rpy="0.314 0 3.14" xyz="0.022 -0.025 -.045"/>
    <dynamics damping="0.7"/>
  </joint>
  <joint name="left_thumb1_thumb2" type="revolute">
    <parent link="leftbigfingerseg1"/>
    <child link="leftbigfingerseg2"/>
    <origin rpy="-0.314 0 0" xyz="0 0 -0.02"/>
    <limit effort="1000.0" lower="0" upper="0.707" velocity="0.5"/>
    <axis xyz="-1.0 0 0"/>
    <dynamics damping="0.7"/>
  </joint>
  <joint name="left_thumb2_thumb3" type="revolute">
    <parent link="leftbigfingerseg2"/>
    <child link="leftbigfingerseg3"/>
    <origin rpy="-0.314 0 0" xyz="0 0 -0.02"/>
    <limit effort="1000.0" lower="0" upper="0.707" velocity="0.5"/>
    <axis xyz="-1.0 0 0"/>
    <dynamics damping="0.7"/>
  </joint>
  <link name="leftf41">
    <visual>
      <geometry>
        <mesh filename="package://ar600_description/meshes/finger_segment.dae"/>
      </geometry>
    </visual>
    <inertial>
      <mass value="0.05"/>
      <inertia ixx="1.0" ixy="0.0" ixz="0.0" iyy="1.0" iyz="0.0" izz="1.0"/>
    </inertial>
    <collision>
      <geometry>
        <mesh filename="package://ar600_description/meshes/finger_segment.stl"/>
      </geometry>
    </collision>
  </link>
  <link name="leftf42">
    <visual>
      <geometry>
        <mesh filename="package://ar600_description/meshes/finger_segment.dae"/>
      </geometry>
    </visual>
    <inertial>
      <mass value="0.05"/>
      <inertia ixx="1.0" ixy="0.0" ixz="0.0" iyy="1.0" iyz="0.0" izz="1.0"/>
    </inertial>
    <collision>
      <geometry>
        <mesh filename="package://ar600_description/meshes/finger_segment.stl"/>
      </geometry>
    </collision>
  </link>
  <link name="leftf43">
    <visual>
      <geometry>
        <mesh filename="package://ar600_description/meshes/finger_tip.dae"/>
      </geometry>
    </visual>
    <inertial>
      <mass value="0.05"/>
      <inertia ixx="1.0" ixy="0.0" ixz="0.0" iyy="1.0" iyz="0.0" izz="1.0"/>
    </inertial>
    <collision>
      <geometry>
        <mesh filename="package://ar600_description/meshes/finger_segment.stl"/>
      </geometry>
    </collision>
  </link>
  <joint name="left_palm_f4" type="fixed">
    <parent link="left_palm"/>
    <child link="leftf41"/>
    <origin rpy="0 0 0" xyz="-0.03 0.01 -0.0575"/>
    <dynamics damping="0.7"/>
  </joint>
  <joint name="left_f41_f42" type="revolute">
    <parent link="leftf41"/>
    <child link="leftf42"/>
    <origin rpy="0 0 0" xyz="0 0 -0.02"/>
    <limit effort="1000.0" lower="0" upper="0.707" velocity="0.5"/>
    <axis xyz="-1.0 0 0"/>
    <dynamics damping="0.7"/>
  </joint>
  <joint name="left_f42_f43" type="revolute">
    <parent link="leftf42"/>
    <child link="leftf43"/>
    <origin rpy="0 0 0" xyz="0 0 -0.02"/>
    <limit effort="1000.0" lower="0" upper="0.707" velocity="0.5"/>
    <axis xyz="-1.0 0 0"/>
    <dynamics damping="0.7"/>
  </joint>
  <link name="leftf11">
    <visual>
      <geometry>
        <mesh filename="package://ar600_description/meshes/finger_segment.dae"/>
      </geometry>
    </visual>
    <inertial>
      <mass value="0.05"/>
      <inertia ixx="1.0" ixy="0.0" ixz="0.0" iyy="1.0" iyz="0.0" izz="1.0"/>
    </inertial>
    <collision>
      <geometry>
        <mesh filename="package://ar600_description/meshes/finger_segment.stl"/>
      </geometry>
    </collision>
  </link>
  <link name="leftf12">
    <visual>
      <geometry>
        <mesh filename="package://ar600_description/meshes/finger_segment.dae"/>
      </geometry>
    </visual>
    <inertial>
      <mass value="0.05"/>
      <inertia ixx="1.0" ixy="0.0" ixz="0.0" iyy="1.0" iyz="0.0" izz="1.0"/>
    </inertial>
    <collision>
      <geometry>
        <mesh filename="package://ar600_description/meshes/finger_segment.stl"/>
      </geometry>
    </collision>
  </link>
  <link name="leftf13">
    <visual>
      <geometry>
        <mesh filename="package://ar600_description/meshes/finger_segment.dae"/>
      </geometry>
    </visual>
    <inertial>
      <mass value="0.05"/>
      <inertia ixx="1.0" ixy="0.0" ixz="0.0" iyy="1.0" iyz="0.0" izz="1.0"/>
    </inertial>
    <collision>
      <geometry>
        <mesh filename="package://ar600_description/meshes/finger_segment.stl"/>
      </geometry>
    </collision>
  </link>
  <link name="leftf14">
    <visual>
      <geometry>
        <mesh filename="package://ar600_description/meshes/finger_tip.dae"/>
      </geometry>
    </visual>
    <inertial>
      <mass value="0.05"/>
      <inertia ixx="1.0" ixy="0.0" ixz="0.0" iyy="1.0" iyz="0.0" izz="1.0"/>
    </inertial>
    <collision>
      <geometry>
        <mesh filename="package://ar600_description/meshes/finger_segment.stl"/>
      </geometry>
    </collision>
  </link>
  <joint name="left_palm_f1" type="fixed">
    <parent link="left_palm"/>
    <child link="leftf11"/>
    <origin rpy="0 0 0" xyz="0.022 0.01 -0.0625"/>
  </joint>
  <joint name="left_f11_f12" type="revolute">
    <parent link="leftf11"/>
    <child link="leftf12"/>
    <origin rpy="0 0 0" xyz="0 0 -0.02"/>
    <limit effort="1000.0" lower="0" upper="0.707" velocity="0.5"/>
    <axis xyz="-1.0 0 0"/>
  </joint>
  <joint name="left_f12_f13" type="revolute">
    <parent link="leftf12"/>
    <child link="leftf13"/>
    <origin rpy="0 0 0" xyz="0 0 -0.02"/>
    <limit effort="1000.0" lower="0" upper="0.707" velocity="0.5"/>
    <axis xyz="-1.0 0 0"/>
  </joint>
  <joint name="left_f13_f14" type="revolute">
    <parent link="leftf13"/>
    <child link="leftf14"/>
    <origin rpy="0 0 0" xyz="0 0 -0.02"/>
    <limit effort="1000.0" lower="0" upper="0.707" velocity="0.5"/>
    <axis xyz="-1.0 0 0"/>
  </joint>
  <link name="leftf21">
    <visual>
      <geometry>
        <mesh filename="package://ar600_description/meshes/finger_segment.dae"/>
      </geometry>
    </visual>
    <inertial>
      <mass value="0.05"/>
      <inertia ixx="1.0" ixy="0.0" ixz="0.0" iyy="1.0" iyz="0.0" izz="1.0"/>
    </inertial>
    <collision>
      <geometry>
        <mesh filename="package://ar600_description/meshes/finger_segment.stl"/>
      </geometry>
    </collision>
  </link>
  <link name="leftf22">
    <visual>
      <geometry>
        <mesh filename="package://ar600_description/meshes/finger_segment.dae"/>
      </geometry>
    </visual>
    <inertial>
      <mass value="0.05"/>
      <inertia ixx="1.0" ixy="0.0" ixz="0.0" iyy="1.0" iyz="0.0" izz="1.0"/>
    </inertial>
    <collision>
      <geometry>
        <mesh filename="package://ar600_description/meshes/finger_segment.stl"/>
      </geometry>
    </collision>
  </link>
  <link name="leftf23">
    <visual>
      <geometry>
        <mesh filename="package://ar600_description/meshes/finger_segment.dae"/>
      </geometry>
    </visual>
    <inertial>
      <mass value="0.05"/>
      <inertia ixx="1.0" ixy="0.0" ixz="0.0" iyy="1.0" iyz="0.0" izz="1.0"/>
    </inertial>
    <collision>
      <geometry>
        <mesh filename="package://ar600_description/meshes/finger_segment.stl"/>
      </geometry>
    </collision>
  </link>
  <link name="leftf24">
    <visual>
      <geometry>
        <mesh filename="package://ar600_description/meshes/finger_tip.dae"/>
      </geometry>
    </visual>
    <inertial>
      <mass value="0.05"/>
      <inertia ixx="1.0" ixy="0.0" ixz="0.0" iyy="1.0" iyz="0.0" izz="1.0"/>
    </inertial>
    <collision>
      <geometry>
        <mesh filename="package://ar600_description/meshes/finger_segment.stl"/>
      </geometry>
    </collision>
  </link>
  <joint name="left_palm_f2" type="fixed">
    <parent link="left_palm"/>
    <child link="leftf21"/>
    <origin rpy="0 0 0" xyz="0.004 0.01 -0.068"/>
  </joint>
  <joint name="left_f21_f22" type="revolute">
    <parent link="leftf21"/>
    <child link="leftf22"/>
    <origin rpy="0 0 0" xyz="0 0 -0.02"/>
    <limit effort="1000.0" lower="0" upper="0.707" velocity="0.5"/>
    <axis xyz="-1.0 0 0"/>
  </joint>
  <joint name="left_f22_f23" type="revolute">
    <parent link="leftf22"/>
    <child link="leftf23"/>
    <origin rpy="0 0 0" xyz="0 0 -0.02"/>
    <limit effort="1000.0" lower="0" upper="0.707" velocity="0.5"/>
    <axis xyz="-1.0 0 0"/>
  </joint>
  <joint name="left_f23_f24" type="revolute">
    <parent link="leftf23"/>
    <child link="leftf24"/>
    <origin rpy="0 0 0" xyz="0 0 -0.02"/>
    <limit effort="1000.0" lower="0" upper="0.707" velocity="0.5"/>
    <axis xyz="-1.0 0 0"/>
  </joint>
  <link name="leftf31">
    <visual>
      <geometry>
        <mesh filename="package://ar600_description/meshes/finger_segment.dae"/>
      </geometry>
    </visual>
    <inertial>
      <mass value="0.05"/>
      <inertia ixx="1.0" ixy="0.0" ixz="0.0" iyy="1.0" iyz="0.0" izz="1.0"/>
    </inertial>
    <collision>
      <geometry>
        <mesh filename="package://ar600_description/meshes/finger_segment.stl"/>
      </geometry>
    </collision>
  </link>
  <link name="leftf32">
    <visual>
      <geometry>
        <mesh filename="package://ar600_description/meshes/finger_segment.dae"/>
      </geometry>
    </visual>
    <inertial>
      <mass value="0.05"/>
      <inertia ixx="1.0" ixy="0.0" ixz="0.0" iyy="1.0" iyz="0.0" izz="1.0"/>
    </inertial>
    <collision>
      <geometry>
        <mesh filename="package://ar600_description/meshes/finger_segment.stl"/>
      </geometry>
    </collision>
  </link>
  <link name="leftf33">
    <visual>
      <geometry>
        <mesh filename="package://ar600_description/meshes/finger_segment.dae"/>
      </geometry>
    </visual>
    <inertial>
      <mass value="0.05"/>
      <inertia ixx="1.0" ixy="0.0" ixz="0.0" iyy="1.0" iyz="0.0" izz="1.0"/>
    </inertial>
    <collision>
      <geometry>
        <mesh filename="package://ar600_description/meshes/finger_segment.stl"/>
      </geometry>
    </collision>
  </link>
  <link name="leftf34">
    <visual>
      <geometry>
        <mesh filename="package://ar600_description/meshes/finger_tip.dae"/>
      </geometry>
    </visual>
    <inertial>
      <mass value="0.05"/>
      <inertia ixx="1.0" ixy="0.0" ixz="0.0" iyy="1.0" iyz="0.0" izz="1.0"/>
    </inertial>
    <collision>
      <geometry>
        <mesh filename="package://ar600_description/meshes/finger_segment.stl"/>
      </geometry>
    </collision>
  </link>
  <joint name="left_palm_f3" type="fixed">
    <parent link="left_palm"/>
    <child link="leftf31"/>
    <origin rpy="0 0 0" xyz="-0.013 0.01 -0.0625"/>
  </joint>
  <joint name="left_f31_f32" type="revolute">
    <parent link="leftf31"/>
    <child link="leftf32"/>
    <origin rpy="0 0 0" xyz="0 0 -0.02"/>
    <limit effort="1000.0" lower="0" upper="0.707" velocity="0.5"/>
    <axis xyz="-1.0 0 0"/>
  </joint>
  <joint name="left_f32_f33" type="revolute">
    <parent link="leftf32"/>
    <child link="leftf33"/>
    <origin rpy="0 0 0" xyz="0 0 -0.02"/>
    <limit effort="1000.0" lower="0" upper="0.707" velocity="0.5"/>
    <axis xyz="-1.0 0 0"/>
  </joint>
  <joint name="left_f33_f34" type="revolute">
    <parent link="leftf33"/>
    <child link="leftf34"/>
    <origin rpy="0 0 0" xyz="0 0 -0.02"/>
    <limit effort="1000.0" lower="0" upper="0.707" velocity="0.5"/>
    <axis xyz="-1.0 0 0"/>
  </joint>
</robot>

