<?xml version="1.0" ?>
<!-- =================================================================================== -->
<!-- |    This document was autogenerated by xacro from ar600.urdf.xacro               | -->
<!-- |    EDITING THIS FILE BY HAND IS NOT RECOMMENDED                                 | -->
<!-- =================================================================================== -->
<robot name="ar600" xmlns:xacro="http://ros.org/wiki/xacro">
  <gazebo>
    <plugin filename="libgazebo_ros_control.so" name="gazebo_ros_control">
      <robotNamespace>/ar600</robotNamespace>
    </plugin>
    <!-- 	<plugin name="gazebo_ros_controller_manager" filename="libgazebo_ros_controller_manager.so">
    	<alwaysOn>true</alwaysOn>
    	<updateRate>1000.0</updateRate>
    	<robotNamespace>/ar600</robotNamespace>
    </plugin>
 -->
  </gazebo>
  <!--<xacro:include filename="$(find ar600_description)/urdf/base/base.transmission.xacro" />-->
  <!--<xacro:include filename="$(find ar600_description)/urdf/head/head.transmission.xacro" />-->
  <!--<xacro:include filename="$(find ar600_description)/urdf/leg/leg.transmission.xacro" />-->
  <!--<xacro:include filename="$(find ar600_description)/urdf/hand/hand.transmission.xacro" />-->
  <link name="base_link">
    <inertial>
      <mass value="10"/>
      <inertia ixx="1.0" ixy="0.0" ixz="0.0" iyy="1.0" iyz="0.0" izz="1.0"/>
    </inertial>
    <collision>
      <geometry>
        <mesh filename="package://ar600_description/meshes/base.stl"/>
      </geometry>
    </collision>
    <visual>
      <geometry>
        <mesh filename="package://ar600_description/meshes/base_low.dae"/>
      </geometry>
    </visual>
  </link>
  <link name="torso_link">
    <inertial>
      <mass value="30"/>
      <inertia ixx="1.0" ixy="0.0" ixz="0.0" iyy="1.0" iyz="0.0" izz="1.0"/>
    </inertial>
    <collision>
      <geometry>
        <mesh filename="package://ar600_description/meshes/body.stl"/>
      </geometry>
    </collision>
    <visual>
      <geometry>
        <mesh filename="package://ar600_description/meshes/body.dae"/>
      </geometry>
    </visual>
  </link>
  <joint name="torso_rotation_joint" type="revolute">
    <axis xyz="0 0 1"/>
    <dynamics damping="0.7"/>
    <parent link="base_link"/>
    <child link="torso_link"/>
    <limit effort="1000.0" lower="-.5" upper=".5" velocity="0.5"/>
    <origin rpy="0 0 0" xyz="0 0 0"/>
  </joint>
  <gazebo reference="base_link">
    <selfCollide>false</selfCollide>
    <mu1>0.2</mu1>
    <mu2>0.2</mu2>
    <material>Gazebo/Black</material>
  </gazebo>
  <gazebo reference="base_link">
    <selfCollide>false</selfCollide>
    <mu1>0.2</mu1>
    <mu2>0.2</mu2>
  </gazebo>
  <!--<xacro:ar600_base_torso_transmission/>-->
  <link name="head_link">
    <visual>
      <geometry>
        <mesh filename="package://ar600_description/meshes/head_low.dae"/>
      </geometry>
    </visual>
    <inertial>
      <mass value="1"/>
      <inertia ixx="1.0" ixy="0.0" ixz="0.0" iyy="1.0" iyz="0.0" izz="1.0"/>
    </inertial>
    <collision>
      <geometry>
        <mesh filename="package://ar600_description/meshes/phys_model/head.stl"/>
      </geometry>
    </collision>
  </link>
  <link name="head_mount">
    <inertial>
      <mass value=".1"/>
      <inertia ixx="1.0" ixy="0.0" ixz="0.0" iyy="1.0" iyz="0.0" izz="1.0"/>
    </inertial>
  </link>
  <link name="head_tilt_mount">
    <inertial>
      <mass value=".1"/>
      <inertia ixx="1.0" ixy="0.0" ixz="0.0" iyy="1.0" iyz="0.0" izz="1.0"/>
    </inertial>
  </link>
  <joint name="torso_head_mount" type="revolute">
    <parent link="torso_link"/>
    <child link="head_mount"/>
    <origin rpy="0 0 0" xyz="-0.05 0 .37"/>
    <limit effort="1000.0" lower="-0.548" upper="0.548" velocity="0.5"/>
    <axis xyz="0 0 1"/>
    <dynamics damping="0.7"/>
  </joint>
  <joint name="mount_head_tilt_mount" type="revolute">
    <parent link="head_mount"/>
    <child link="head_tilt_mount"/>
    <origin rpy="0 0 0" xyz="0 0 0"/>
    <limit effort="1000.0" lower="-.1" upper="0.1" velocity="0.5"/>
    <axis xyz="1 0 0"/>
    <dynamics damping="0.7"/>
  </joint>
  <joint name="head_mount_head" type="revolute">
    <parent link="head_tilt_mount"/>
    <child link="head_link"/>
    <limit effort="1000.0" lower="-0.25" upper="0.25" velocity="0.5"/>
    <axis xyz="0 1 0"/>
    <dynamics damping="0.7"/>
    <origin rpy="0 0 0" xyz="0 0 0"/>
  </joint>
  <!--<xacro:ar600_head_transmission/>-->
  <link name="base_right_hip">
    <visual>
      <geometry>
        <mesh filename="package://ar600_description/meshes/right_base_leg_low.dae"/>
      </geometry>
    </visual>
    <inertial>
      <mass value="5"/>
      <inertia ixx="1.0" ixy="0.0" ixz="0.0" iyy="1.0" iyz="0.0" izz="1.0"/>
    </inertial>
  </link>
  <link name="right_hip_mount">
    <inertial>
      <mass value="1"/>
      <inertia ixx="1.0" ixy="0.0" ixz="0.0" iyy="1.0" iyz="0.0" izz="1.0"/>
    </inertial>
  </link>
  <link name="right_hip">
    <visual>
      <geometry>
        <mesh filename="package://ar600_description/meshes/right_leg_low.dae"/>
      </geometry>
    </visual>
    <inertial>
      <mass value="5"/>
      <inertia ixx="1.0" ixy="0.0" ixz="0.0" iyy="1.0" iyz="0.0" izz="1.0"/>
    </inertial>
    <collision>
      <geometry>
        <mesh filename="package://ar600_description/meshes/phys_model/hip.stl"/>
      </geometry>
    </collision>
  </link>
  <link name="right_shin">
    <visual>
      <geometry>
        <mesh filename="package://ar600_description/meshes/shin_low.dae"/>
      </geometry>
    </visual>
    <inertial>
      <mass value="5"/>
      <inertia ixx="1.0" ixy="0.0" ixz="0.0" iyy="1.0" iyz="0.0" izz="1.0"/>
    </inertial>
    <collision>
      <geometry>
        <mesh filename="package://ar600_description/meshes/phys_model/phys_shin.stl"/>
      </geometry>
    </collision>
  </link>
  <link name="right_shin_foot_mount">
    <inertial>
      <mass value="1"/>
      <inertia ixx="1.0" ixy="0.0" ixz="0.0" iyy="1.0" iyz="0.0" izz="1.0"/>
    </inertial>
  </link>
  <link name="right_foot">
    <visual>
      <geometry>
        <mesh filename="package://ar600_description/meshes/right_foot_low.dae"/>
      </geometry>
    </visual>
    <inertial>
      <mass value="2"/>
      <inertia ixx="1.0" ixy="0.0" ixz="0.0" iyy="1.0" iyz="0.0" izz="1.0"/>
    </inertial>
    <collision>
      <geometry>
        <mesh filename="package://ar600_description/meshes/phys_model/foot.stl"/>
      </geometry>
    </collision>
  </link>
  <joint name="base_right_leg_joint" type="revolute">
    <parent link="base_link"/>
    <child link="base_right_hip"/>
    <origin rpy=" 0 0 0" xyz="0.025 -.1 -0.085"/>
    <axis xyz="0 0 -1"/>
    <limit effort="1000.0" lower="0.5" upper="-0.5" velocity="0.5"/>
    <dynamics damping="0.7"/>
  </joint>
  <joint name="right_base_mount" type="revolute">
    <parent link="base_right_hip"/>
    <child link="right_hip_mount"/>
    <origin rpy=" 0 0 0" xyz="0.0267 0 -.154"/>
    <limit effort="1000.0" lower="0.5" upper="-0.5" velocity="0.5"/>
    <axis xyz="-1 0 0"/>
    <dynamics damping="0.7"/>
  </joint>
  <joint name="right_base_mount_hip" type="revolute">
    <parent link="right_hip_mount"/>
    <child link="right_hip"/>
    <origin rpy="0 0 0" xyz="0 0 0"/>
    <limit effort="1000.0" lower="-.5" upper=".5" velocity="0.5"/>
    <axis xyz="0 -1 0"/>
    <dynamics damping="0.7"/>
  </joint>
  <joint name="right_hip_right_shin" type="revolute">
    <parent link="right_hip"/>
    <child link="right_shin"/>
    <origin rpy="0 0 0" xyz="0 -0.01 -.335"/>
    <limit effort="1000.0" lower="0" upper=".707" velocity="0.5"/>
    <axis xyz="0 1 0"/>
    <dynamics damping="0.7"/>
  </joint>
  <joint name="right_shin_right_foot_mount" type="revolute">
    <parent link="right_shin"/>
    <child link="right_shin_foot_mount"/>
    <origin rpy="0 0 0" xyz="0 0 -.26"/>
    <limit effort="1000.0" lower="-.707" upper=".707" velocity="0.5"/>
    <axis xyz="0 1 0"/>
    <dynamics damping="0.7"/>
  </joint>
  <joint name="right_shin_mount_right_foot" type="revolute">
    <parent link="right_shin_foot_mount"/>
    <child link="right_foot"/>
    <limit effort="1000.0" lower="0.707" upper="-0.707" velocity="0.5"/>
    <axis xyz="-1 0 0"/>
    <dynamics damping="0.7"/>
  </joint>
  <!--<xacro:base_leg_joint_controller_macro side="${side}"/>
		<xacro:base_mount_controller_macro side="${side}"/>
		<xacro:base_mount_hip_controller_macro side="${side}"/>
		<xacro:hip_shin_controller_macro side="${side}"/>
		<xacro:shin_foot_mount_controller_macro side="${side}"/>
		<xacro:shin_mount_foot_controller_macro side="${side}"/>-->
  <link name="base_left_hip">
    <visual>
      <geometry>
        <mesh filename="package://ar600_description/meshes/left_base_leg_low.dae"/>
      </geometry>
    </visual>
    <inertial>
      <mass value="5"/>
      <inertia ixx="1.0" ixy="0.0" ixz="0.0" iyy="1.0" iyz="0.0" izz="1.0"/>
    </inertial>
  </link>
  <link name="left_hip_mount">
    <inertial>
      <mass value="1"/>
      <inertia ixx="1.0" ixy="0.0" ixz="0.0" iyy="1.0" iyz="0.0" izz="1.0"/>
    </inertial>
  </link>
  <link name="left_hip">
    <visual>
      <geometry>
        <mesh filename="package://ar600_description/meshes/left_leg_low.dae"/>
      </geometry>
    </visual>
    <inertial>
      <mass value="5"/>
      <inertia ixx="1.0" ixy="0.0" ixz="0.0" iyy="1.0" iyz="0.0" izz="1.0"/>
    </inertial>
    <collision>
      <geometry>
        <mesh filename="package://ar600_description/meshes/phys_model/hip.stl"/>
      </geometry>
    </collision>
  </link>
  <link name="left_shin">
    <visual>
      <geometry>
        <mesh filename="package://ar600_description/meshes/shin_low.dae"/>
      </geometry>
    </visual>
    <inertial>
      <mass value="5"/>
      <inertia ixx="1.0" ixy="0.0" ixz="0.0" iyy="1.0" iyz="0.0" izz="1.0"/>
    </inertial>
    <collision>
      <geometry>
        <mesh filename="package://ar600_description/meshes/phys_model/phys_shin.stl"/>
      </geometry>
    </collision>
  </link>
  <link name="left_shin_foot_mount">
    <inertial>
      <mass value="1"/>
      <inertia ixx="1.0" ixy="0.0" ixz="0.0" iyy="1.0" iyz="0.0" izz="1.0"/>
    </inertial>
  </link>
  <link name="left_foot">
    <visual>
      <geometry>
        <mesh filename="package://ar600_description/meshes/left_foot_low.dae"/>
      </geometry>
    </visual>
    <inertial>
      <mass value="2"/>
      <inertia ixx="1.0" ixy="0.0" ixz="0.0" iyy="1.0" iyz="0.0" izz="1.0"/>
    </inertial>
    <collision>
      <geometry>
        <mesh filename="package://ar600_description/meshes/phys_model/foot.stl"/>
      </geometry>
    </collision>
  </link>
  <joint name="base_left_leg_joint" type="revolute">
    <parent link="base_link"/>
    <child link="base_left_hip"/>
    <origin rpy=" 0 0 0" xyz="0.025 .1 -0.085"/>
    <axis xyz="0 0 1"/>
    <limit effort="1000.0" lower="-0.5" upper="0.5" velocity="0.5"/>
    <dynamics damping="0.7"/>
  </joint>
  <joint name="left_base_mount" type="revolute">
    <parent link="base_left_hip"/>
    <child link="left_hip_mount"/>
    <origin rpy=" 0 0 0" xyz="0.0267 0 -.154"/>
    <limit effort="1000.0" lower="-0.5" upper="0.5" velocity="0.5"/>
    <axis xyz="1 0 0"/>
    <dynamics damping="0.7"/>
  </joint>
  <joint name="left_base_mount_hip" type="revolute">
    <parent link="left_hip_mount"/>
    <child link="left_hip"/>
    <origin rpy="0 0 0" xyz="0 0 0"/>
    <limit effort="1000.0" lower="-.5" upper=".5" velocity="0.5"/>
    <axis xyz="0 -1 0"/>
    <dynamics damping="0.7"/>
  </joint>
  <joint name="left_hip_left_shin" type="revolute">
    <parent link="left_hip"/>
    <child link="left_shin"/>
    <origin rpy="0 0 0" xyz="0 0.01 -.335"/>
    <limit effort="1000.0" lower="0" upper=".707" velocity="0.5"/>
    <axis xyz="0 1 0"/>
    <dynamics damping="0.7"/>
  </joint>
  <joint name="left_shin_left_foot_mount" type="revolute">
    <parent link="left_shin"/>
    <child link="left_shin_foot_mount"/>
    <origin rpy="0 0 0" xyz="0 0 -.26"/>
    <limit effort="1000.0" lower="-.707" upper=".707" velocity="0.5"/>
    <axis xyz="0 1 0"/>
    <dynamics damping="0.7"/>
  </joint>
  <joint name="left_shin_mount_left_foot" type="revolute">
    <parent link="left_shin_foot_mount"/>
    <child link="left_foot"/>
    <limit effort="1000.0" lower="-0.707" upper="0.707" velocity="0.5"/>
    <axis xyz="1 0 0"/>
    <dynamics damping="0.7"/>
  </joint>
  <!--<xacro:base_leg_joint_controller_macro side="${side}"/>
		<xacro:base_mount_controller_macro side="${side}"/>
		<xacro:base_mount_hip_controller_macro side="${side}"/>
		<xacro:hip_shin_controller_macro side="${side}"/>
		<xacro:shin_foot_mount_controller_macro side="${side}"/>
		<xacro:shin_mount_foot_controller_macro side="${side}"/>-->
  <link name="left_shoulder">
    <visual>
      <geometry>
        <mesh filename="package://ar600_description/meshes/left_shoulder_low.dae"/>
      </geometry>
    </visual>
    <inertial>
      <mass value="1"/>
      <inertia ixx="1.0" ixy="0.0" ixz="0.0" iyy="1.0" iyz="0.0" izz="1.0"/>
    </inertial>
  </link>
  <link name="left_upper_forearm">
    <visual>
      <geometry>
        <mesh filename="package://ar600_description/meshes/left_upper_arm_high.dae"/>
      </geometry>
    </visual>
    <inertial>
      <mass value="4"/>
      <inertia ixx="1.0" ixy="0.0" ixz="0.0" iyy="1.0" iyz="0.0" izz="1.0"/>
    </inertial>
    <collision>
      <geometry>
        <mesh filename="package://ar600_description/meshes/phys_model/forearm.stl"/>
      </geometry>
    </collision>
  </link>
  <link name="left_elbow">
    <visual>
      <geometry>
        <mesh filename="package://ar600_description/meshes/elbow_low.dae"/>
      </geometry>
    </visual>
    <inertial>
      <mass value="1"/>
      <inertia ixx="1.0" ixy="0.0" ixz="0.0" iyy="1.0" iyz="0.0" izz="1.0"/>
    </inertial>
    <collision>
      <geometry>
        <mesh filename="package://ar600_description/meshes/phys_model/elbow.stl"/>
      </geometry>
    </collision>
  </link>
  <link name="left_arm_link">
    <visual>
      <geometry>
        <mesh filename="package://ar600_description/meshes/left_arm.dae"/>
      </geometry>
    </visual>
    <inertial>
      <mass value="3"/>
      <inertia ixx="1.0" ixy="0.0" ixz="0.0" iyy="1.0" iyz="0.0" izz="1.0"/>
    </inertial>
    <collision>
      <geometry>
        <mesh filename="package://ar600_description/meshes/phys_model/arm.stl"/>
      </geometry>
    </collision>
  </link>
  <link name="left_hand_effector_link">
    <inertial>
      <mass value=".1"/>
      <inertia ixx="1.0" ixy="0.0" ixz="0.0" iyy="1.0" iyz="0.0" izz="1.0"/>
    </inertial>
  </link>
  <joint name="torso_left_shoulder" type="revolute">
    <parent link="torso_link"/>
    <child link="left_shoulder"/>
    <origin rpy="1.57 1.2 1.57" xyz="-0.01 0.12 .25"/>
    <limit effort="1000.0" lower="0" upper="3.14" velocity="0.5"/>
    <axis xyz="0 -1 0"/>
    <dynamics damping="0.7"/>
  </joint>
  <joint name="left_upper_forearm_shoulder" type="revolute">
    <parent link="left_shoulder"/>
    <child link="left_upper_forearm"/>
    <origin rpy="-1.57 0 1.57" xyz="0 0.055 0"/>
    <limit effort="1000.0" lower="0.0" upper="1.57" velocity="0.5"/>
    <axis xyz="0 -1 0"/>
    <dynamics damping="0.7"/>
  </joint>
  <joint name="left_upper_forearm_left_lower_forearm" type="revolute">
    <parent link="left_upper_forearm"/>
    <child link="left_elbow"/>
    <origin rpy="0 0 0" xyz="0 0 -0.12"/>
    <limit effort="1000.0" lower="-1.57" upper="1.57" velocity="0.5"/>
    <axis xyz="0 0 1"/>
    <dynamics damping="0.7"/>
  </joint>
  <joint name="left_lower_forearm_arm" type="revolute">
    <parent link="left_elbow"/>
    <child link="left_arm_link"/>
    <origin rpy="0 0 0" xyz="0 0 -0.1"/>
    <limit effort="1000.0" lower="0" upper="1.57" velocity="0.5"/>
    <axis xyz="-1 0 0"/>
    <dynamics damping="0.7"/>
  </joint>
  <joint name="left_lower_arm_effector" type="revolute">
    <parent link="left_arm_link"/>
    <child link="left_hand_effector_link"/>
    <limit effort="1000.0" lower="-0.707" upper="0.707" velocity="0.5"/>
    <origin rpy="0 0 0" xyz="0.005 0.005 -0.21"/>
    <axis xyz="0 0 -1"/>
    <dynamics damping="0.7"/>
  </joint>
  <!--<xacro:shoulder_transmission_macro side="${side}"/>
		<xacro:upper_forearm_shoulder_transmission_macro side="${side}"/>
		<xacro:upper_forearm_lower_forearm_transmission_macro side="${side}"/>
		<xacro:elbow_transmission_macro side="${side}"/>
		<xacro:arm_transmission_macro side="${side}"/>-->
  <link name="right_shoulder">
    <visual>
      <geometry>
        <mesh filename="package://ar600_description/meshes/right_shoulder_low.dae"/>
      </geometry>
    </visual>
    <inertial>
      <mass value="1"/>
      <inertia ixx="1.0" ixy="0.0" ixz="0.0" iyy="1.0" iyz="0.0" izz="1.0"/>
    </inertial>
  </link>
  <link name="right_upper_forearm">
    <visual>
      <geometry>
        <mesh filename="package://ar600_description/meshes/right_upper_arm_high.dae"/>
      </geometry>
    </visual>
    <inertial>
      <mass value="4"/>
      <inertia ixx="1.0" ixy="0.0" ixz="0.0" iyy="1.0" iyz="0.0" izz="1.0"/>
    </inertial>
    <collision>
      <geometry>
        <mesh filename="package://ar600_description/meshes/phys_model/forearm.stl"/>
      </geometry>
    </collision>
  </link>
  <link name="right_elbow">
    <visual>
      <geometry>
        <mesh filename="package://ar600_description/meshes/elbow_low.dae"/>
      </geometry>
    </visual>
    <inertial>
      <mass value="1"/>
      <inertia ixx="1.0" ixy="0.0" ixz="0.0" iyy="1.0" iyz="0.0" izz="1.0"/>
    </inertial>
    <collision>
      <geometry>
        <mesh filename="package://ar600_description/meshes/phys_model/elbow.stl"/>
      </geometry>
    </collision>
  </link>
  <link name="right_arm_link">
    <visual>
      <geometry>
        <mesh filename="package://ar600_description/meshes/right_arm.dae"/>
      </geometry>
    </visual>
    <inertial>
      <mass value="3"/>
      <inertia ixx="1.0" ixy="0.0" ixz="0.0" iyy="1.0" iyz="0.0" izz="1.0"/>
    </inertial>
    <collision>
      <geometry>
        <mesh filename="package://ar600_description/meshes/phys_model/arm.stl"/>
      </geometry>
    </collision>
  </link>
  <link name="right_hand_effector_link">
    <inertial>
      <mass value=".1"/>
      <inertia ixx="1.0" ixy="0.0" ixz="0.0" iyy="1.0" iyz="0.0" izz="1.0"/>
    </inertial>
  </link>
  <joint name="torso_right_shoulder" type="revolute">
    <parent link="torso_link"/>
    <child link="right_shoulder"/>
    <origin rpy="-1.57 1.2 -1.57" xyz="-0.01 -0.12 .25"/>
    <limit effort="1000.0" lower="0" upper="3.14" velocity="0.5"/>
    <axis xyz="0 -1 0"/>
    <dynamics damping="0.7"/>
  </joint>
  <joint name="right_upper_forearm_shoulder" type="revolute">
    <parent link="right_shoulder"/>
    <child link="right_upper_forearm"/>
    <origin rpy="-1.57 0 1.57" xyz="0 -0.055 0"/>
    <limit effort="1000.0" lower="0.0" upper="1.57" velocity="0.5"/>
    <axis xyz="0 1 0"/>
    <dynamics damping="0.7"/>
  </joint>
  <joint name="right_upper_forearm_right_lower_forearm" type="revolute">
    <parent link="right_upper_forearm"/>
    <child link="right_elbow"/>
    <origin rpy="0 0 0" xyz="0 0 -0.12"/>
    <limit effort="1000.0" lower="-1.57" upper="1.57" velocity="0.5"/>
    <axis xyz="0 0 -1"/>
    <dynamics damping="0.7"/>
  </joint>
  <joint name="right_lower_forearm_arm" type="revolute">
    <parent link="right_elbow"/>
    <child link="right_arm_link"/>
    <origin rpy="0 0 0" xyz="0 0 -0.1"/>
    <limit effort="1000.0" lower="0" upper="1.57" velocity="0.5"/>
    <axis xyz="-1 0 0"/>
    <dynamics damping="0.7"/>
  </joint>
  <joint name="right_lower_arm_effector" type="revolute">
    <parent link="right_arm_link"/>
    <child link="right_hand_effector_link"/>
    <limit effort="1000.0" lower="-0.707" upper="0.707" velocity="0.5"/>
    <origin rpy="0 0 0" xyz="0.005 0.005 -0.21"/>
    <axis xyz="0 0 -1"/>
    <dynamics damping="0.7"/>
  </joint>
  <!--<xacro:shoulder_transmission_macro side="${side}"/>
		<xacro:upper_forearm_shoulder_transmission_macro side="${side}"/>
		<xacro:upper_forearm_lower_forearm_transmission_macro side="${side}"/>
		<xacro:elbow_transmission_macro side="${side}"/>
		<xacro:arm_transmission_macro side="${side}"/>-->
  <link name="right_palm">
    <visual>
      <geometry>
        <mesh filename="package://ar600_description/meshes/right_palm_vis.dae"/>
      </geometry>
    </visual>
    <inertial>
      <mass value="0.1"/>
      <inertia ixx="1.0" ixy="0.0" ixz="0.0" iyy="1.0" iyz="0.0" izz="1.0"/>
    </inertial>
    <collision>
      <geometry>
        <mesh filename="package://ar600_description/meshes/right_palm.stl"/>
      </geometry>
    </collision>
  </link>
  <link name="rightbigfingerseg1">
    <visual>
      <geometry>
        <mesh filename="package://ar600_description/meshes/finger_segment.dae"/>
      </geometry>
    </visual>
    <inertial>
      <mass value="0.05"/>
      <inertia ixx="1.0" ixy="0.0" ixz="0.0" iyy="1.0" iyz="0.0" izz="1.0"/>
    </inertial>
    <collision>
      <geometry>
        <mesh filename="package://ar600_description/meshes/finger_segment.stl"/>
      </geometry>
    </collision>
  </link>
  <link name="rightbigfingerseg2">
    <visual>
      <geometry>
        <mesh filename="package://ar600_description/meshes/finger_segment.dae"/>
      </geometry>
    </visual>
    <inertial>
      <mass value="0.05"/>
      <inertia ixx="1.0" ixy="0.0" ixz="0.0" iyy="1.0" iyz="0.0" izz="1.0"/>
    </inertial>
    <collision>
      <geometry>
        <mesh filename="package://ar600_description/meshes/finger_segment.stl"/>
      </geometry>
    </collision>
  </link>
  <link name="rightbigfingerseg3">
    <visual>
      <geometry>
        <mesh filename="package://ar600_description/meshes/finger_tip.dae"/>
      </geometry>
    </visual>
    <inertial>
      <mass value="0.05"/>
      <inertia ixx="1.0" ixy="0.0" ixz="0.0" iyy="1.0" iyz="0.0" izz="1.0"/>
    </inertial>
    <collision>
      <geometry>
        <mesh filename="package://ar600_description/meshes/finger_segment.stl"/>
      </geometry>
    </collision>
  </link>
  <joint name="arm_right_palm" type="revolute">
    <parent link="right_hand_effector_link"/>
    <child link="right_palm"/>
    <origin rpy="0 0 1.57" xyz="0 0 0"/>
    <limit effort="1000.0" lower="-0.707" upper="0.707" velocity="0.5"/>
    <axis xyz="0 0 1"/>
    <dynamics damping="0.7"/>
  </joint>
  <joint name="right_palm_thumb1" type="fixed">
    <parent link="right_palm"/>
    <child link="rightbigfingerseg1"/>
    <origin rpy="0.314 0 3.14" xyz="-0.022 -0.025 -.045"/>
    <dynamics damping="0.7"/>
  </joint>
  <joint name="right_thumb1_thumb2" type="revolute">
    <parent link="rightbigfingerseg1"/>
    <child link="rightbigfingerseg2"/>
    <origin rpy="-0.314 0 0" xyz="0 0 -0.02"/>
    <limit effort="1000.0" lower="0" upper="0.707" velocity="0.5"/>
    <axis xyz="1 0 0"/>
    <dynamics damping="0.7"/>
  </joint>
  <joint name="right_thumb2_thumb3" type="revolute">
    <parent link="rightbigfingerseg2"/>
    <child link="rightbigfingerseg3"/>
    <origin rpy="-0.314 0 0" xyz="0 0 -0.02"/>
    <limit effort="1000.0" lower="0" upper="0.707" velocity="0.5"/>
    <axis xyz="1 0 0"/>
    <dynamics damping="0.7"/>
  </joint>
  <link name="rightf41">
    <visual>
      <geometry>
        <mesh filename="package://ar600_description/meshes/finger_segment.dae"/>
      </geometry>
    </visual>
    <inertial>
      <mass value="0.05"/>
      <inertia ixx="1.0" ixy="0.0" ixz="0.0" iyy="1.0" iyz="0.0" izz="1.0"/>
    </inertial>
    <collision>
      <geometry>
        <mesh filename="package://ar600_description/meshes/finger_segment.stl"/>
      </geometry>
    </collision>
  </link>
  <link name="rightf42">
    <visual>
      <geometry>
        <mesh filename="package://ar600_description/meshes/finger_segment.dae"/>
      </geometry>
    </visual>
    <inertial>
      <mass value="0.05"/>
      <inertia ixx="1.0" ixy="0.0" ixz="0.0" iyy="1.0" iyz="0.0" izz="1.0"/>
    </inertial>
    <collision>
      <geometry>
        <mesh filename="package://ar600_description/meshes/finger_segment.stl"/>
      </geometry>
    </collision>
  </link>
  <link name="rightf43">
    <visual>
      <geometry>
        <mesh filename="package://ar600_description/meshes/finger_tip.dae"/>
      </geometry>
    </visual>
    <inertial>
      <mass value="0.05"/>
      <inertia ixx="1.0" ixy="0.0" ixz="0.0" iyy="1.0" iyz="0.0" izz="1.0"/>
    </inertial>
    <collision>
      <geometry>
        <mesh filename="package://ar600_description/meshes/finger_segment.stl"/>
      </geometry>
    </collision>
  </link>
  <joint name="right_palm_f4" type="fixed">
    <parent link="right_palm"/>
    <child link="rightf41"/>
    <origin rpy="0 0 0" xyz="0.03 0.01 -0.0575"/>
    <dynamics damping="0.7"/>
  </joint>
  <joint name="right_f41_f42" type="revolute">
    <parent link="rightf41"/>
    <child link="rightf42"/>
    <origin rpy="0 0 0" xyz="0 0 -0.02"/>
    <limit effort="1000.0" lower="0" upper="0.707" velocity="0.5"/>
    <axis xyz="1 0 0"/>
    <dynamics damping="0.7"/>
  </joint>
  <joint name="right_f42_f43" type="revolute">
    <parent link="rightf42"/>
    <child link="rightf43"/>
    <origin rpy="0 0 0" xyz="0 0 -0.02"/>
    <limit effort="1000.0" lower="0" upper="0.707" velocity="0.5"/>
    <axis xyz="1 0 0"/>
    <dynamics damping="0.7"/>
  </joint>
  <link name="rightf11">
    <visual>
      <geometry>
        <mesh filename="package://ar600_description/meshes/finger_segment.dae"/>
      </geometry>
    </visual>
    <inertial>
      <mass value="0.05"/>
      <inertia ixx="1.0" ixy="0.0" ixz="0.0" iyy="1.0" iyz="0.0" izz="1.0"/>
    </inertial>
    <collision>
      <geometry>
        <mesh filename="package://ar600_description/meshes/finger_segment.stl"/>
      </geometry>
    </collision>
  </link>
  <link name="rightf12">
    <visual>
      <geometry>
        <mesh filename="package://ar600_description/meshes/finger_segment.dae"/>
      </geometry>
    </visual>
    <inertial>
      <mass value="0.05"/>
      <inertia ixx="1.0" ixy="0.0" ixz="0.0" iyy="1.0" iyz="0.0" izz="1.0"/>
    </inertial>
    <collision>
      <geometry>
        <mesh filename="package://ar600_description/meshes/finger_segment.stl"/>
      </geometry>
    </collision>
  </link>
  <link name="rightf13">
    <visual>
      <geometry>
        <mesh filename="package://ar600_description/meshes/finger_segment.dae"/>
      </geometry>
    </visual>
    <inertial>
      <mass value="0.05"/>
      <inertia ixx="1.0" ixy="0.0" ixz="0.0" iyy="1.0" iyz="0.0" izz="1.0"/>
    </inertial>
    <collision>
      <geometry>
        <mesh filename="package://ar600_description/meshes/finger_segment.stl"/>
      </geometry>
    </collision>
  </link>
  <link name="rightf14">
    <visual>
      <geometry>
        <mesh filename="package://ar600_description/meshes/finger_tip.dae"/>
      </geometry>
    </visual>
    <inertial>
      <mass value="0.05"/>
      <inertia ixx="1.0" ixy="0.0" ixz="0.0" iyy="1.0" iyz="0.0" izz="1.0"/>
    </inertial>
    <collision>
      <geometry>
        <mesh filename="package://ar600_description/meshes/finger_segment.stl"/>
      </geometry>
    </collision>
  </link>
  <joint name="right_palm_f1" type="fixed">
    <parent link="right_palm"/>
    <child link="rightf11"/>
    <origin rpy="0 0 0" xyz="-0.022 0.01 -0.0625"/>
  </joint>
  <joint name="right_f11_f12" type="revolute">
    <parent link="rightf11"/>
    <child link="rightf12"/>
    <origin rpy="0 0 0" xyz="0 0 -0.02"/>
    <limit effort="1000.0" lower="0" upper="0.707" velocity="0.5"/>
    <axis xyz="1 0 0"/>
  </joint>
  <joint name="right_f12_f13" type="revolute">
    <parent link="rightf12"/>
    <child link="rightf13"/>
    <origin rpy="0 0 0" xyz="0 0 -0.02"/>
    <limit effort="1000.0" lower="0" upper="0.707" velocity="0.5"/>
    <axis xyz="1 0 0"/>
  </joint>
  <joint name="right_f13_f14" type="revolute">
    <parent link="rightf13"/>
    <child link="rightf14"/>
    <origin rpy="0 0 0" xyz="0 0 -0.02"/>
    <limit effort="1000.0" lower="0" upper="0.707" velocity="0.5"/>
    <axis xyz="1 0 0"/>
  </joint>
  <link name="rightf21">
    <visual>
      <geometry>
        <mesh filename="package://ar600_description/meshes/finger_segment.dae"/>
      </geometry>
    </visual>
    <inertial>
      <mass value="0.05"/>
      <inertia ixx="1.0" ixy="0.0" ixz="0.0" iyy="1.0" iyz="0.0" izz="1.0"/>
    </inertial>
    <collision>
      <geometry>
        <mesh filename="package://ar600_description/meshes/finger_segment.stl"/>
      </geometry>
    </collision>
  </link>
  <link name="rightf22">
    <visual>
      <geometry>
        <mesh filename="package://ar600_description/meshes/finger_segment.dae"/>
      </geometry>
    </visual>
    <inertial>
      <mass value="0.05"/>
      <inertia ixx="1.0" ixy="0.0" ixz="0.0" iyy="1.0" iyz="0.0" izz="1.0"/>
    </inertial>
    <collision>
      <geometry>
        <mesh filename="package://ar600_description/meshes/finger_segment.stl"/>
      </geometry>
    </collision>
  </link>
  <link name="rightf23">
    <visual>
      <geometry>
        <mesh filename="package://ar600_description/meshes/finger_segment.dae"/>
      </geometry>
    </visual>
    <inertial>
      <mass value="0.05"/>
      <inertia ixx="1.0" ixy="0.0" ixz="0.0" iyy="1.0" iyz="0.0" izz="1.0"/>
    </inertial>
    <collision>
      <geometry>
        <mesh filename="package://ar600_description/meshes/finger_segment.stl"/>
      </geometry>
    </collision>
  </link>
  <link name="rightf24">
    <visual>
      <geometry>
        <mesh filename="package://ar600_description/meshes/finger_tip.dae"/>
      </geometry>
    </visual>
    <inertial>
      <mass value="0.05"/>
      <inertia ixx="1.0" ixy="0.0" ixz="0.0" iyy="1.0" iyz="0.0" izz="1.0"/>
    </inertial>
    <collision>
      <geometry>
        <mesh filename="package://ar600_description/meshes/finger_segment.stl"/>
      </geometry>
    </collision>
  </link>
  <joint name="right_palm_f2" type="fixed">
    <parent link="right_palm"/>
    <child link="rightf21"/>
    <origin rpy="0 0 0" xyz="-0.004 0.01 -0.068"/>
  </joint>
  <joint name="right_f21_f22" type="revolute">
    <parent link="rightf21"/>
    <child link="rightf22"/>
    <origin rpy="0 0 0" xyz="0 0 -0.02"/>
    <limit effort="1000.0" lower="0" upper="0.707" velocity="0.5"/>
    <axis xyz="1 0 0"/>
  </joint>
  <joint name="right_f22_f23" type="revolute">
    <parent link="rightf22"/>
    <child link="rightf23"/>
    <origin rpy="0 0 0" xyz="0 0 -0.02"/>
    <limit effort="1000.0" lower="0" upper="0.707" velocity="0.5"/>
    <axis xyz="1 0 0"/>
  </joint>
  <joint name="right_f23_f24" type="revolute">
    <parent link="rightf23"/>
    <child link="rightf24"/>
    <origin rpy="0 0 0" xyz="0 0 -0.02"/>
    <limit effort="1000.0" lower="0" upper="0.707" velocity="0.5"/>
    <axis xyz="1 0 0"/>
  </joint>
  <link name="rightf31">
    <visual>
      <geometry>
        <mesh filename="package://ar600_description/meshes/finger_segment.dae"/>
      </geometry>
    </visual>
    <inertial>
      <mass value="0.05"/>
      <inertia ixx="1.0" ixy="0.0" ixz="0.0" iyy="1.0" iyz="0.0" izz="1.0"/>
    </inertial>
    <collision>
      <geometry>
        <mesh filename="package://ar600_description/meshes/finger_segment.stl"/>
      </geometry>
    </collision>
  </link>
  <link name="rightf32">
    <visual>
      <geometry>
        <mesh filename="package://ar600_description/meshes/finger_segment.dae"/>
      </geometry>
    </visual>
    <inertial>
      <mass value="0.05"/>
      <inertia ixx="1.0" ixy="0.0" ixz="0.0" iyy="1.0" iyz="0.0" izz="1.0"/>
    </inertial>
    <collision>
      <geometry>
        <mesh filename="package://ar600_description/meshes/finger_segment.stl"/>
      </geometry>
    </collision>
  </link>
  <link name="rightf33">
    <visual>
      <geometry>
        <mesh filename="package://ar600_description/meshes/finger_segment.dae"/>
      </geometry>
    </visual>
    <inertial>
      <mass value="0.05"/>
      <inertia ixx="1.0" ixy="0.0" ixz="0.0" iyy="1.0" iyz="0.0" izz="1.0"/>
    </inertial>
    <collision>
      <geometry>
        <mesh filename="package://ar600_description/meshes/finger_segment.stl"/>
      </geometry>
    </collision>
  </link>
  <link name="rightf34">
    <visual>
      <geometry>
        <mesh filename="package://ar600_description/meshes/finger_tip.dae"/>
      </geometry>
    </visual>
    <inertial>
      <mass value="0.05"/>
      <inertia ixx="1.0" ixy="0.0" ixz="0.0" iyy="1.0" iyz="0.0" izz="1.0"/>
    </inertial>
    <collision>
      <geometry>
        <mesh filename="package://ar600_description/meshes/finger_segment.stl"/>
      </geometry>
    </collision>
  </link>
  <joint name="right_palm_f3" type="fixed">
    <parent link="right_palm"/>
    <child link="rightf31"/>
    <origin rpy="0 0 0" xyz="0.013 0.01 -0.0625"/>
  </joint>
  <joint name="right_f31_f32" type="revolute">
    <parent link="rightf31"/>
    <child link="rightf32"/>
    <origin rpy="0 0 0" xyz="0 0 -0.02"/>
    <limit effort="1000.0" lower="0" upper="0.707" velocity="0.5"/>
    <axis xyz="1 0 0"/>
  </joint>
  <joint name="right_f32_f33" type="revolute">
    <parent link="rightf32"/>
    <child link="rightf33"/>
    <origin rpy="0 0 0" xyz="0 0 -0.02"/>
    <limit effort="1000.0" lower="0" upper="0.707" velocity="0.5"/>
    <axis xyz="1 0 0"/>
  </joint>
  <joint name="right_f33_f34" type="revolute">
    <parent link="rightf33"/>
    <child link="rightf34"/>
    <origin rpy="0 0 0" xyz="0 0 -0.02"/>
    <limit effort="1000.0" lower="0" upper="0.707" velocity="0.5"/>
    <axis xyz="1 0 0"/>
  </joint>
  <link name="left_palm">
    <visual>
      <geometry>
        <mesh filename="package://ar600_description/meshes/left_palm_vis.dae"/>
      </geometry>
    </visual>
    <inertial>
      <mass value="0.1"/>
      <inertia ixx="1.0" ixy="0.0" ixz="0.0" iyy="1.0" iyz="0.0" izz="1.0"/>
    </inertial>
    <collision>
      <geometry>
        <mesh filename="package://ar600_description/meshes/left_palm.stl"/>
      </geometry>
    </collision>
  </link>
  <link name="leftbigfingerseg1">
    <visual>
      <geometry>
        <mesh filename="package://ar600_description/meshes/finger_segment.dae"/>
      </geometry>
    </visual>
    <inertial>
      <mass value="0.05"/>
      <inertia ixx="1.0" ixy="0.0" ixz="0.0" iyy="1.0" iyz="0.0" izz="1.0"/>
    </inertial>
    <collision>
      <geometry>
        <mesh filename="package://ar600_description/meshes/finger_segment.stl"/>
      </geometry>
    </collision>
  </link>
  <link name="leftbigfingerseg2">
    <visual>
      <geometry>
        <mesh filename="package://ar600_description/meshes/finger_segment.dae"/>
      </geometry>
    </visual>
    <inertial>
      <mass value="0.05"/>
      <inertia ixx="1.0" ixy="0.0" ixz="0.0" iyy="1.0" iyz="0.0" izz="1.0"/>
    </inertial>
    <collision>
      <geometry>
        <mesh filename="package://ar600_description/meshes/finger_segment.stl"/>
      </geometry>
    </collision>
  </link>
  <link name="leftbigfingerseg3">
    <visual>
      <geometry>
        <mesh filename="package://ar600_description/meshes/finger_tip.dae"/>
      </geometry>
    </visual>
    <inertial>
      <mass value="0.05"/>
      <inertia ixx="1.0" ixy="0.0" ixz="0.0" iyy="1.0" iyz="0.0" izz="1.0"/>
    </inertial>
    <collision>
      <geometry>
        <mesh filename="package://ar600_description/meshes/finger_segment.stl"/>
      </geometry>
    </collision>
  </link>
  <joint name="arm_left_palm" type="revolute">
    <parent link="left_hand_effector_link"/>
    <child link="left_palm"/>
    <origin rpy="0 0 -1.57" xyz="0 0 0"/>
    <limit effort="1000.0" lower="-0.707" upper="0.707" velocity="0.5"/>
    <axis xyz="0 0 -1"/>
    <dynamics damping="0.7"/>
  </joint>
  <joint name="left_palm_thumb1" type="fixed">
    <parent link="left_palm"/>
    <child link="leftbigfingerseg1"/>
    <origin rpy="0.314 0 3.14" xyz="0.022 -0.025 -.045"/>
    <dynamics damping="0.7"/>
  </joint>
  <joint name="left_thumb1_thumb2" type="revolute">
    <parent link="leftbigfingerseg1"/>
    <child link="leftbigfingerseg2"/>
    <origin rpy="-0.314 0 0" xyz="0 0 -0.02"/>
    <limit effort="1000.0" lower="0" upper="0.707" velocity="0.5"/>
    <axis xyz="-1 0 0"/>
    <dynamics damping="0.7"/>
  </joint>
  <joint name="left_thumb2_thumb3" type="revolute">
    <parent link="leftbigfingerseg2"/>
    <child link="leftbigfingerseg3"/>
    <origin rpy="-0.314 0 0" xyz="0 0 -0.02"/>
    <limit effort="1000.0" lower="0" upper="0.707" velocity="0.5"/>
    <axis xyz="-1 0 0"/>
    <dynamics damping="0.7"/>
  </joint>
  <link name="leftf41">
    <visual>
      <geometry>
        <mesh filename="package://ar600_description/meshes/finger_segment.dae"/>
      </geometry>
    </visual>
    <inertial>
      <mass value="0.05"/>
      <inertia ixx="1.0" ixy="0.0" ixz="0.0" iyy="1.0" iyz="0.0" izz="1.0"/>
    </inertial>
    <collision>
      <geometry>
        <mesh filename="package://ar600_description/meshes/finger_segment.stl"/>
      </geometry>
    </collision>
  </link>
  <link name="leftf42">
    <visual>
      <geometry>
        <mesh filename="package://ar600_description/meshes/finger_segment.dae"/>
      </geometry>
    </visual>
    <inertial>
      <mass value="0.05"/>
      <inertia ixx="1.0" ixy="0.0" ixz="0.0" iyy="1.0" iyz="0.0" izz="1.0"/>
    </inertial>
    <collision>
      <geometry>
        <mesh filename="package://ar600_description/meshes/finger_segment.stl"/>
      </geometry>
    </collision>
  </link>
  <link name="leftf43">
    <visual>
      <geometry>
        <mesh filename="package://ar600_description/meshes/finger_tip.dae"/>
      </geometry>
    </visual>
    <inertial>
      <mass value="0.05"/>
      <inertia ixx="1.0" ixy="0.0" ixz="0.0" iyy="1.0" iyz="0.0" izz="1.0"/>
    </inertial>
    <collision>
      <geometry>
        <mesh filename="package://ar600_description/meshes/finger_segment.stl"/>
      </geometry>
    </collision>
  </link>
  <joint name="left_palm_f4" type="fixed">
    <parent link="left_palm"/>
    <child link="leftf41"/>
    <origin rpy="0 0 0" xyz="-0.03 0.01 -0.0575"/>
    <dynamics damping="0.7"/>
  </joint>
  <joint name="left_f41_f42" type="revolute">
    <parent link="leftf41"/>
    <child link="leftf42"/>
    <origin rpy="0 0 0" xyz="0 0 -0.02"/>
    <limit effort="1000.0" lower="0" upper="0.707" velocity="0.5"/>
    <axis xyz="-1 0 0"/>
    <dynamics damping="0.7"/>
  </joint>
  <joint name="left_f42_f43" type="revolute">
    <parent link="leftf42"/>
    <child link="leftf43"/>
    <origin rpy="0 0 0" xyz="0 0 -0.02"/>
    <limit effort="1000.0" lower="0" upper="0.707" velocity="0.5"/>
    <axis xyz="-1 0 0"/>
    <dynamics damping="0.7"/>
  </joint>
  <link name="leftf11">
    <visual>
      <geometry>
        <mesh filename="package://ar600_description/meshes/finger_segment.dae"/>
      </geometry>
    </visual>
    <inertial>
      <mass value="0.05"/>
      <inertia ixx="1.0" ixy="0.0" ixz="0.0" iyy="1.0" iyz="0.0" izz="1.0"/>
    </inertial>
    <collision>
      <geometry>
        <mesh filename="package://ar600_description/meshes/finger_segment.stl"/>
      </geometry>
    </collision>
  </link>
  <link name="leftf12">
    <visual>
      <geometry>
        <mesh filename="package://ar600_description/meshes/finger_segment.dae"/>
      </geometry>
    </visual>
    <inertial>
      <mass value="0.05"/>
      <inertia ixx="1.0" ixy="0.0" ixz="0.0" iyy="1.0" iyz="0.0" izz="1.0"/>
    </inertial>
    <collision>
      <geometry>
        <mesh filename="package://ar600_description/meshes/finger_segment.stl"/>
      </geometry>
    </collision>
  </link>
  <link name="leftf13">
    <visual>
      <geometry>
        <mesh filename="package://ar600_description/meshes/finger_segment.dae"/>
      </geometry>
    </visual>
    <inertial>
      <mass value="0.05"/>
      <inertia ixx="1.0" ixy="0.0" ixz="0.0" iyy="1.0" iyz="0.0" izz="1.0"/>
    </inertial>
    <collision>
      <geometry>
        <mesh filename="package://ar600_description/meshes/finger_segment.stl"/>
      </geometry>
    </collision>
  </link>
  <link name="leftf14">
    <visual>
      <geometry>
        <mesh filename="package://ar600_description/meshes/finger_tip.dae"/>
      </geometry>
    </visual>
    <inertial>
      <mass value="0.05"/>
      <inertia ixx="1.0" ixy="0.0" ixz="0.0" iyy="1.0" iyz="0.0" izz="1.0"/>
    </inertial>
    <collision>
      <geometry>
        <mesh filename="package://ar600_description/meshes/finger_segment.stl"/>
      </geometry>
    </collision>
  </link>
  <joint name="left_palm_f1" type="fixed">
    <parent link="left_palm"/>
    <child link="leftf11"/>
    <origin rpy="0 0 0" xyz="0.022 0.01 -0.0625"/>
  </joint>
  <joint name="left_f11_f12" type="revolute">
    <parent link="leftf11"/>
    <child link="leftf12"/>
    <origin rpy="0 0 0" xyz="0 0 -0.02"/>
    <limit effort="1000.0" lower="0" upper="0.707" velocity="0.5"/>
    <axis xyz="-1 0 0"/>
  </joint>
  <joint name="left_f12_f13" type="revolute">
    <parent link="leftf12"/>
    <child link="leftf13"/>
    <origin rpy="0 0 0" xyz="0 0 -0.02"/>
    <limit effort="1000.0" lower="0" upper="0.707" velocity="0.5"/>
    <axis xyz="-1 0 0"/>
  </joint>
  <joint name="left_f13_f14" type="revolute">
    <parent link="leftf13"/>
    <child link="leftf14"/>
    <origin rpy="0 0 0" xyz="0 0 -0.02"/>
    <limit effort="1000.0" lower="0" upper="0.707" velocity="0.5"/>
    <axis xyz="-1 0 0"/>
  </joint>
  <link name="leftf21">
    <visual>
      <geometry>
        <mesh filename="package://ar600_description/meshes/finger_segment.dae"/>
      </geometry>
    </visual>
    <inertial>
      <mass value="0.05"/>
      <inertia ixx="1.0" ixy="0.0" ixz="0.0" iyy="1.0" iyz="0.0" izz="1.0"/>
    </inertial>
    <collision>
      <geometry>
        <mesh filename="package://ar600_description/meshes/finger_segment.stl"/>
      </geometry>
    </collision>
  </link>
  <link name="leftf22">
    <visual>
      <geometry>
        <mesh filename="package://ar600_description/meshes/finger_segment.dae"/>
      </geometry>
    </visual>
    <inertial>
      <mass value="0.05"/>
      <inertia ixx="1.0" ixy="0.0" ixz="0.0" iyy="1.0" iyz="0.0" izz="1.0"/>
    </inertial>
    <collision>
      <geometry>
        <mesh filename="package://ar600_description/meshes/finger_segment.stl"/>
      </geometry>
    </collision>
  </link>
  <link name="leftf23">
    <visual>
      <geometry>
        <mesh filename="package://ar600_description/meshes/finger_segment.dae"/>
      </geometry>
    </visual>
    <inertial>
      <mass value="0.05"/>
      <inertia ixx="1.0" ixy="0.0" ixz="0.0" iyy="1.0" iyz="0.0" izz="1.0"/>
    </inertial>
    <collision>
      <geometry>
        <mesh filename="package://ar600_description/meshes/finger_segment.stl"/>
      </geometry>
    </collision>
  </link>
  <link name="leftf24">
    <visual>
      <geometry>
        <mesh filename="package://ar600_description/meshes/finger_tip.dae"/>
      </geometry>
    </visual>
    <inertial>
      <mass value="0.05"/>
      <inertia ixx="1.0" ixy="0.0" ixz="0.0" iyy="1.0" iyz="0.0" izz="1.0"/>
    </inertial>
    <collision>
      <geometry>
        <mesh filename="package://ar600_description/meshes/finger_segment.stl"/>
      </geometry>
    </collision>
  </link>
  <joint name="left_palm_f2" type="fixed">
    <parent link="left_palm"/>
    <child link="leftf21"/>
    <origin rpy="0 0 0" xyz="0.004 0.01 -0.068"/>
  </joint>
  <joint name="left_f21_f22" type="revolute">
    <parent link="leftf21"/>
    <child link="leftf22"/>
    <origin rpy="0 0 0" xyz="0 0 -0.02"/>
    <limit effort="1000.0" lower="0" upper="0.707" velocity="0.5"/>
    <axis xyz="-1 0 0"/>
  </joint>
  <joint name="left_f22_f23" type="revolute">
    <parent link="leftf22"/>
    <child link="leftf23"/>
    <origin rpy="0 0 0" xyz="0 0 -0.02"/>
    <limit effort="1000.0" lower="0" upper="0.707" velocity="0.5"/>
    <axis xyz="-1 0 0"/>
  </joint>
  <joint name="left_f23_f24" type="revolute">
    <parent link="leftf23"/>
    <child link="leftf24"/>
    <origin rpy="0 0 0" xyz="0 0 -0.02"/>
    <limit effort="1000.0" lower="0" upper="0.707" velocity="0.5"/>
    <axis xyz="-1 0 0"/>
  </joint>
  <link name="leftf31">
    <visual>
      <geometry>
        <mesh filename="package://ar600_description/meshes/finger_segment.dae"/>
      </geometry>
    </visual>
    <inertial>
      <mass value="0.05"/>
      <inertia ixx="1.0" ixy="0.0" ixz="0.0" iyy="1.0" iyz="0.0" izz="1.0"/>
    </inertial>
    <collision>
      <geometry>
        <mesh filename="package://ar600_description/meshes/finger_segment.stl"/>
      </geometry>
    </collision>
  </link>
  <link name="leftf32">
    <visual>
      <geometry>
        <mesh filename="package://ar600_description/meshes/finger_segment.dae"/>
      </geometry>
    </visual>
    <inertial>
      <mass value="0.05"/>
      <inertia ixx="1.0" ixy="0.0" ixz="0.0" iyy="1.0" iyz="0.0" izz="1.0"/>
    </inertial>
    <collision>
      <geometry>
        <mesh filename="package://ar600_description/meshes/finger_segment.stl"/>
      </geometry>
    </collision>
  </link>
  <link name="leftf33">
    <visual>
      <geometry>
        <mesh filename="package://ar600_description/meshes/finger_segment.dae"/>
      </geometry>
    </visual>
    <inertial>
      <mass value="0.05"/>
      <inertia ixx="1.0" ixy="0.0" ixz="0.0" iyy="1.0" iyz="0.0" izz="1.0"/>
    </inertial>
    <collision>
      <geometry>
        <mesh filename="package://ar600_description/meshes/finger_segment.stl"/>
      </geometry>
    </collision>
  </link>
  <link name="leftf34">
    <visual>
      <geometry>
        <mesh filename="package://ar600_description/meshes/finger_tip.dae"/>
      </geometry>
    </visual>
    <inertial>
      <mass value="0.05"/>
      <inertia ixx="1.0" ixy="0.0" ixz="0.0" iyy="1.0" iyz="0.0" izz="1.0"/>
    </inertial>
    <collision>
      <geometry>
        <mesh filename="package://ar600_description/meshes/finger_segment.stl"/>
      </geometry>
    </collision>
  </link>
  <joint name="left_palm_f3" type="fixed">
    <parent link="left_palm"/>
    <child link="leftf31"/>
    <origin rpy="0 0 0" xyz="-0.013 0.01 -0.0625"/>
  </joint>
  <joint name="left_f31_f32" type="revolute">
    <parent link="leftf31"/>
    <child link="leftf32"/>
    <origin rpy="0 0 0" xyz="0 0 -0.02"/>
    <limit effort="1000.0" lower="0" upper="0.707" velocity="0.5"/>
    <axis xyz="-1 0 0"/>
  </joint>
  <joint name="left_f32_f33" type="revolute">
    <parent link="leftf32"/>
    <child link="leftf33"/>
    <origin rpy="0 0 0" xyz="0 0 -0.02"/>
    <limit effort="1000.0" lower="0" upper="0.707" velocity="0.5"/>
    <axis xyz="-1 0 0"/>
  </joint>
  <joint name="left_f33_f34" type="revolute">
    <parent link="leftf33"/>
    <child link="leftf34"/>
    <origin rpy="0 0 0" xyz="0 0 -0.02"/>
    <limit effort="1000.0" lower="0" upper="0.707" velocity="0.5"/>
    <axis xyz="-1 0 0"/>
  </joint>
</robot>
